{
  "id": "7",
  "name": "Test Run 7",
  "status": "failed",
  "created_at": "2025-06-13T04:27:50.164948+00:00",
  "duration": 7.212319100692327,
  "total_tests": 29,
  "tests_passed": 15,
  "tests_failed": 4,
  "tests_error": 0,
  "tests_skipped": 0,
  "branch": "main",
  "commit_hash": "abc123def456",
  "triggered_by": "tester",
  "metadata": {
    "environment": "development",
    "python_version": "3.9.7",
    "django_version": "3.2.9"
  },
  "test_cases": [
    {
      "nodeid": "test_module_0.py::test_case_0",
      "name": "test_case_0",
      "file": "/path/to/test_module_0.py",
      "line": 70,
      "status": "error",
      "duration": 0.48111751586175294,
      "message": "Test case failed",
      "traceback": "Traceback (most recent call last):\n  File \"test.py\", line 2, in <module>\n    assert False\nAssertionError"
    },
    {
      "nodeid": "test_module_1.py::test_case_1",
      "name": "test_case_1",
      "file": "/path/to/test_module_1.py",
      "line": 55,
      "status": "xfailed",
      "duration": 0.9370054607164263,
      "message": "Test case failed",
      "traceback": "Traceback (most recent call last):\n  File \"test.py\", line 2, in <module>\n    assert False\nAssertionError"
    },
    {
      "nodeid": "test_module_10.py::test_case_10",
      "name": "test_case_10",
      "file": "/path/to/test_module_10.py",
      "line": 93,
      "status": "xfailed",
      "duration": 2.2026027742855327,
      "message": "Test case failed",
      "traceback": "Traceback (most recent call last):\n  File \"test.py\", line 2, in <module>\n    assert False\nAssertionError"
    },
    {
      "nodeid": "test_module_11.py::test_case_11",
      "name": "test_case_11",
      "file": "/path/to/test_module_11.py",
      "line": 94,
      "status": "error",
      "duration": 0.7348456180584549,
      "message": "Test case failed",
      "traceback": "Traceback (most recent call last):\n  File \"test.py\", line 2, in <module>\n    assert False\nAssertionError"
    },
    {
      "nodeid": "test_module_12.py::test_case_12",
      "name": "test_case_12",
      "file": "/path/to/test_module_12.py",
      "line": 89,
      "status": "passed",
      "duration": 0.479189400933972,
      "message": "Test case executed successfully",
      "traceback": ""
    },
    {
      "nodeid": "test_module_2.py::test_case_2",
      "name": "test_case_2",
      "file": "/path/to/test_module_2.py",
      "line": 61,
      "status": "xfailed",
      "duration": 0.013801239785666199,
      "message": "Test case failed",
      "traceback": "Traceback (most recent call last):\n  File \"test.py\", line 2, in <module>\n    assert False\nAssertionError"
    },
    {
      "nodeid": "test_module_3.py::test_case_3",
      "name": "test_case_3",
      "file": "/path/to/test_module_3.py",
      "line": 87,
      "status": "failed",
      "duration": 1.7972415453783173,
      "message": "Test case failed",
      "traceback": "Traceback (most recent call last):\n  File \"test.py\", line 2, in <module>\n    assert False\nAssertionError"
    },
    {
      "nodeid": "test_module_4.py::test_case_4",
      "name": "test_case_4",
      "file": "/path/to/test_module_4.py",
      "line": 26,
      "status": "passed",
      "duration": 1.2415270496972848,
      "message": "Test case executed successfully",
      "traceback": ""
    },
    {
      "nodeid": "test_module_5.py::test_case_5",
      "name": "test_case_5",
      "file": "/path/to/test_module_5.py",
      "line": 17,
      "status": "xpassed",
      "duration": 1.9334782571316123,
      "message": "Test case failed",
      "traceback": "Traceback (most recent call last):\n  File \"test.py\", line 2, in <module>\n    assert False\nAssertionError"
    },
    {
      "nodeid": "test_module_6.py::test_case_6",
      "name": "test_case_6",
      "file": "/path/to/test_module_6.py",
      "line": 78,
      "status": "skipped",
      "duration": 0.19409539573233978,
      "message": "Test case failed",
      "traceback": "Traceback (most recent call last):\n  File \"test.py\", line 2, in <module>\n    assert False\nAssertionError"
    },
    {
      "nodeid": "test_module_7.py::test_case_7",
      "name": "test_case_7",
      "file": "/path/to/test_module_7.py",
      "line": 23,
      "status": "skipped",
      "duration": 0.6783526501219804,
      "message": "Test case failed",
      "traceback": "Traceback (most recent call last):\n  File \"test.py\", line 2, in <module>\n    assert False\nAssertionError"
    },
    {
      "nodeid": "test_module_8.py::test_case_8",
      "name": "test_case_8",
      "file": "/path/to/test_module_8.py",
      "line": 67,
      "status": "xfailed",
      "duration": 0.49560780741416766,
      "message": "Test case failed",
      "traceback": "Traceback (most recent call last):\n  File \"test.py\", line 2, in <module>\n    assert False\nAssertionError"
    },
    {
      "nodeid": "test_module_9.py::test_case_9",
      "name": "test_case_9",
      "file": "/path/to/test_module_9.py",
      "line": 75,
      "status": "xpassed",
      "duration": 1.427291031930608,
      "message": "Test case failed",
      "traceback": "Traceback (most recent call last):\n  File \"test.py\", line 2, in <module>\n    assert False\nAssertionError"
    }
  ]
}