{
  "id": "3",
  "name": "Test Run 3",
  "status": "failed",
  "created_at": "2025-06-10T04:27:49.963279+00:00",
  "duration": 5.455204235967944,
  "total_tests": 20,
  "tests_passed": 37,
  "tests_failed": 4,
  "tests_error": 0,
  "tests_skipped": 1,
  "branch": "main",
  "commit_hash": "abc123def456",
  "triggered_by": "tester",
  "metadata": {
    "environment": "development",
    "python_version": "3.9.7",
    "django_version": "3.2.9"
  },
  "test_cases": [
    {
      "nodeid": "test_module_0.py::test_case_0",
      "name": "test_case_0",
      "file": "/path/to/test_module_0.py",
      "line": 51,
      "status": "skipped",
      "duration": 1.9709942474519633,
      "message": "Test case failed",
      "traceback": "Traceback (most recent call last):\n  File \"test.py\", line 2, in <module>\n    assert False\nAssertionError"
    },
    {
      "nodeid": "test_module_1.py::test_case_1",
      "name": "test_case_1",
      "file": "/path/to/test_module_1.py",
      "line": 21,
      "status": "xfailed",
      "duration": 2.2631109467344594,
      "message": "Test case failed",
      "traceback": "Traceback (most recent call last):\n  File \"test.py\", line 2, in <module>\n    assert False\nAssertionError"
    },
    {
      "nodeid": "test_module_10.py::test_case_10",
      "name": "test_case_10",
      "file": "/path/to/test_module_10.py",
      "line": 34,
      "status": "skipped",
      "duration": 0.5623136541451723,
      "message": "Test case failed",
      "traceback": "Traceback (most recent call last):\n  File \"test.py\", line 2, in <module>\n    assert False\nAssertionError"
    },
    {
      "nodeid": "test_module_11.py::test_case_11",
      "name": "test_case_11",
      "file": "/path/to/test_module_11.py",
      "line": 38,
      "status": "xpassed",
      "duration": 1.8389456042013612,
      "message": "Test case failed",
      "traceback": "Traceback (most recent call last):\n  File \"test.py\", line 2, in <module>\n    assert False\nAssertionError"
    },
    {
      "nodeid": "test_module_12.py::test_case_12",
      "name": "test_case_12",
      "file": "/path/to/test_module_12.py",
      "line": 74,
      "status": "skipped",
      "duration": 2.134583580005754,
      "message": "Test case failed",
      "traceback": "Traceback (most recent call last):\n  File \"test.py\", line 2, in <module>\n    assert False\nAssertionError"
    },
    {
      "nodeid": "test_module_13.py::test_case_13",
      "name": "test_case_13",
      "file": "/path/to/test_module_13.py",
      "line": 28,
      "status": "error",
      "duration": 1.4294474603269736,
      "message": "Test case failed",
      "traceback": "Traceback (most recent call last):\n  File \"test.py\", line 2, in <module>\n    assert False\nAssertionError"
    },
    {
      "nodeid": "test_module_14.py::test_case_14",
      "name": "test_case_14",
      "file": "/path/to/test_module_14.py",
      "line": 49,
      "status": "failed",
      "duration": 2.1314294507192666,
      "message": "Test case failed",
      "traceback": "Traceback (most recent call last):\n  File \"test.py\", line 2, in <module>\n    assert False\nAssertionError"
    },
    {
      "nodeid": "test_module_15.py::test_case_15",
      "name": "test_case_15",
      "file": "/path/to/test_module_15.py",
      "line": 81,
      "status": "skipped",
      "duration": 0.4324198727085979,
      "message": "Test case failed",
      "traceback": "Traceback (most recent call last):\n  File \"test.py\", line 2, in <module>\n    assert False\nAssertionError"
    },
    {
      "nodeid": "test_module_16.py::test_case_16",
      "name": "test_case_16",
      "file": "/path/to/test_module_16.py",
      "line": 41,
      "status": "skipped",
      "duration": 1.6427047162685946,
      "message": "Test case failed",
      "traceback": "Traceback (most recent call last):\n  File \"test.py\", line 2, in <module>\n    assert False\nAssertionError"
    },
    {
      "nodeid": "test_module_17.py::test_case_17",
      "name": "test_case_17",
      "file": "/path/to/test_module_17.py",
      "line": 70,
      "status": "xfailed",
      "duration": 1.4181943090533453,
      "message": "Test case failed",
      "traceback": "Traceback (most recent call last):\n  File \"test.py\", line 2, in <module>\n    assert False\nAssertionError"
    },
    {
      "nodeid": "test_module_18.py::test_case_18",
      "name": "test_case_18",
      "file": "/path/to/test_module_18.py",
      "line": 100,
      "status": "skipped",
      "duration": 0.07326904912026412,
      "message": "Test case failed",
      "traceback": "Traceback (most recent call last):\n  File \"test.py\", line 2, in <module>\n    assert False\nAssertionError"
    },
    {
      "nodeid": "test_module_2.py::test_case_2",
      "name": "test_case_2",
      "file": "/path/to/test_module_2.py",
      "line": 15,
      "status": "xpassed",
      "duration": 1.9555400803917429,
      "message": "Test case failed",
      "traceback": "Traceback (most recent call last):\n  File \"test.py\", line 2, in <module>\n    assert False\nAssertionError"
    },
    {
      "nodeid": "test_module_3.py::test_case_3",
      "name": "test_case_3",
      "file": "/path/to/test_module_3.py",
      "line": 98,
      "status": "xfailed",
      "duration": 1.921207889784858,
      "message": "Test case failed",
      "traceback": "Traceback (most recent call last):\n  File \"test.py\", line 2, in <module>\n    assert False\nAssertionError"
    },
    {
      "nodeid": "test_module_4.py::test_case_4",
      "name": "test_case_4",
      "file": "/path/to/test_module_4.py",
      "line": 50,
      "status": "skipped",
      "duration": 0.6171567898741729,
      "message": "Test case failed",
      "traceback": "Traceback (most recent call last):\n  File \"test.py\", line 2, in <module>\n    assert False\nAssertionError"
    },
    {
      "nodeid": "test_module_5.py::test_case_5",
      "name": "test_case_5",
      "file": "/path/to/test_module_5.py",
      "line": 11,
      "status": "failed",
      "duration": 0.9233846863292375,
      "message": "Test case failed",
      "traceback": "Traceback (most recent call last):\n  File \"test.py\", line 2, in <module>\n    assert False\nAssertionError"
    },
    {
      "nodeid": "test_module_6.py::test_case_6",
      "name": "test_case_6",
      "file": "/path/to/test_module_6.py",
      "line": 98,
      "status": "xfailed",
      "duration": 0.19986868256315654,
      "message": "Test case failed",
      "traceback": "Traceback (most recent call last):\n  File \"test.py\", line 2, in <module>\n    assert False\nAssertionError"
    },
    {
      "nodeid": "test_module_7.py::test_case_7",
      "name": "test_case_7",
      "file": "/path/to/test_module_7.py",
      "line": 71,
      "status": "passed",
      "duration": 1.437852285059808,
      "message": "Test case executed successfully",
      "traceback": ""
    },
    {
      "nodeid": "test_module_8.py::test_case_8",
      "name": "test_case_8",
      "file": "/path/to/test_module_8.py",
      "line": 45,
      "status": "xpassed",
      "duration": 0.9514913205403469,
      "message": "Test case failed",
      "traceback": "Traceback (most recent call last):\n  File \"test.py\", line 2, in <module>\n    assert False\nAssertionError"
    },
    {
      "nodeid": "test_module_9.py::test_case_9",
      "name": "test_case_9",
      "file": "/path/to/test_module_9.py",
      "line": 65,
      "status": "passed",
      "duration": 1.6669173399465411,
      "message": "Test case executed successfully",
      "traceback": ""
    }
  ]
}