{
  "id": "5",
  "name": "Test Run 5",
  "status": "failed",
  "created_at": "2025-06-03T04:27:50.067762+00:00",
  "duration": 2.179690289110912,
  "total_tests": 14,
  "tests_passed": 37,
  "tests_failed": 3,
  "tests_error": 0,
  "tests_skipped": 1,
  "branch": "main",
  "commit_hash": "abc123def456",
  "triggered_by": "tester",
  "metadata": {
    "environment": "development",
    "python_version": "3.9.7",
    "django_version": "3.2.9"
  },
  "test_cases": [
    {
      "nodeid": "test_module_0.py::test_case_0",
      "name": "test_case_0",
      "file": "/path/to/test_module_0.py",
      "line": 27,
      "status": "passed",
      "duration": 0.9995517862661232,
      "message": "Test case executed successfully",
      "traceback": ""
    },
    {
      "nodeid": "test_module_1.py::test_case_1",
      "name": "test_case_1",
      "file": "/path/to/test_module_1.py",
      "line": 72,
      "status": "xfailed",
      "duration": 1.1607810555409466,
      "message": "Test case failed",
      "traceback": "Traceback (most recent call last):\n  File \"test.py\", line 2, in <module>\n    assert False\nAssertionError"
    },
    {
      "nodeid": "test_module_10.py::test_case_10",
      "name": "test_case_10",
      "file": "/path/to/test_module_10.py",
      "line": 52,
      "status": "passed",
      "duration": 2.4295358510293315,
      "message": "Test case executed successfully",
      "traceback": ""
    },
    {
      "nodeid": "test_module_11.py::test_case_11",
      "name": "test_case_11",
      "file": "/path/to/test_module_11.py",
      "line": 31,
      "status": "xfailed",
      "duration": 0.46113537671362365,
      "message": "Test case failed",
      "traceback": "Traceback (most recent call last):\n  File \"test.py\", line 2, in <module>\n    assert False\nAssertionError"
    },
    {
      "nodeid": "test_module_12.py::test_case_12",
      "name": "test_case_12",
      "file": "/path/to/test_module_12.py",
      "line": 90,
      "status": "xfailed",
      "duration": 0.9242153962475674,
      "message": "Test case failed",
      "traceback": "Traceback (most recent call last):\n  File \"test.py\", line 2, in <module>\n    assert False\nAssertionError"
    },
    {
      "nodeid": "test_module_13.py::test_case_13",
      "name": "test_case_13",
      "file": "/path/to/test_module_13.py",
      "line": 48,
      "status": "failed",
      "duration": 0.3264160109594966,
      "message": "Test case failed",
      "traceback": "Traceback (most recent call last):\n  File \"test.py\", line 2, in <module>\n    assert False\nAssertionError"
    },
    {
      "nodeid": "test_module_14.py::test_case_14",
      "name": "test_case_14",
      "file": "/path/to/test_module_14.py",
      "line": 49,
      "status": "xpassed",
      "duration": 1.037534705266445,
      "message": "Test case failed",
      "traceback": "Traceback (most recent call last):\n  File \"test.py\", line 2, in <module>\n    assert False\nAssertionError"
    },
    {
      "nodeid": "test_module_2.py::test_case_2",
      "name": "test_case_2",
      "file": "/path/to/test_module_2.py",
      "line": 88,
      "status": "failed",
      "duration": 0.7879355466997469,
      "message": "Test case failed",
      "traceback": "Traceback (most recent call last):\n  File \"test.py\", line 2, in <module>\n    assert False\nAssertionError"
    },
    {
      "nodeid": "test_module_3.py::test_case_3",
      "name": "test_case_3",
      "file": "/path/to/test_module_3.py",
      "line": 49,
      "status": "xfailed",
      "duration": 2.259414898941957,
      "message": "Test case failed",
      "traceback": "Traceback (most recent call last):\n  File \"test.py\", line 2, in <module>\n    assert False\nAssertionError"
    },
    {
      "nodeid": "test_module_4.py::test_case_4",
      "name": "test_case_4",
      "file": "/path/to/test_module_4.py",
      "line": 33,
      "status": "xpassed",
      "duration": 0.1854099592942653,
      "message": "Test case failed",
      "traceback": "Traceback (most recent call last):\n  File \"test.py\", line 2, in <module>\n    assert False\nAssertionError"
    },
    {
      "nodeid": "test_module_5.py::test_case_5",
      "name": "test_case_5",
      "file": "/path/to/test_module_5.py",
      "line": 25,
      "status": "skipped",
      "duration": 1.8833782479732828,
      "message": "Test case failed",
      "traceback": "Traceback (most recent call last):\n  File \"test.py\", line 2, in <module>\n    assert False\nAssertionError"
    },
    {
      "nodeid": "test_module_6.py::test_case_6",
      "name": "test_case_6",
      "file": "/path/to/test_module_6.py",
      "line": 35,
      "status": "xpassed",
      "duration": 1.1080625502902026,
      "message": "Test case failed",
      "traceback": "Traceback (most recent call last):\n  File \"test.py\", line 2, in <module>\n    assert False\nAssertionError"
    },
    {
      "nodeid": "test_module_7.py::test_case_7",
      "name": "test_case_7",
      "file": "/path/to/test_module_7.py",
      "line": 29,
      "status": "xfailed",
      "duration": 2.186782251874456,
      "message": "Test case failed",
      "traceback": "Traceback (most recent call last):\n  File \"test.py\", line 2, in <module>\n    assert False\nAssertionError"
    },
    {
      "nodeid": "test_module_8.py::test_case_8",
      "name": "test_case_8",
      "file": "/path/to/test_module_8.py",
      "line": 43,
      "status": "failed",
      "duration": 0.8586139329662237,
      "message": "Test case failed",
      "traceback": "Traceback (most recent call last):\n  File \"test.py\", line 2, in <module>\n    assert False\nAssertionError"
    },
    {
      "nodeid": "test_module_9.py::test_case_9",
      "name": "test_case_9",
      "file": "/path/to/test_module_9.py",
      "line": 87,
      "status": "xpassed",
      "duration": 1.8718024972165987,
      "message": "Test case failed",
      "traceback": "Traceback (most recent call last):\n  File \"test.py\", line 2, in <module>\n    assert False\nAssertionError"
    }
  ]
}