2024-09-28 21:34:54,787 - INFO - /app/actualizador/task.py changed, reloading.
2024-09-28 21:35:25,819 - INFO - /app/actualizador/task.py changed, reloading.
2024-09-28 21:37:03,653 - INFO - /app/actualizador/task.py changed, reloading.
2024-09-28 21:37:15,279 - INFO - /app/actualizador/task.py changed, reloading.
2024-09-28 21:38:05,083 - INFO - file_cache is only supported with oauth2client<4.0.0
2024-09-28 21:38:05,093 - INFO - file_cache is only supported with oauth2client<4.0.0
2024-09-28 21:38:05,102 - INFO - file_cache is only supported with oauth2client<4.0.0
2024-09-28 21:38:18,018 - INFO - file_cache is only supported with oauth2client<4.0.0
2024-09-28 21:38:18,091 - INFO - file_cache is only supported with oauth2client<4.0.0
2024-09-28 21:38:18,303 - INFO - file_cache is only supported with oauth2client<4.0.0
2024-09-28 21:38:18,852 - WARNING - No hostname was supplied. Reverting to default 'localhost'
2024-09-28 21:45:17,779 - INFO - file_cache is only supported with oauth2client<4.0.0
2024-09-28 21:45:17,789 - INFO - file_cache is only supported with oauth2client<4.0.0
2024-09-28 21:45:17,796 - INFO - file_cache is only supported with oauth2client<4.0.0
2024-09-28 21:49:40,285 - INFO - file_cache is only supported with oauth2client<4.0.0
2024-09-28 21:49:40,295 - INFO - file_cache is only supported with oauth2client<4.0.0
2024-09-28 21:49:40,303 - INFO - file_cache is only supported with oauth2client<4.0.0
2024-09-28 22:07:46,473 - INFO - file_cache is only supported with oauth2client<4.0.0
2024-09-28 22:07:46,483 - INFO - file_cache is only supported with oauth2client<4.0.0
2024-09-28 22:07:46,491 - INFO - file_cache is only supported with oauth2client<4.0.0
2024-09-28 22:07:49,397 - INFO - file_cache is only supported with oauth2client<4.0.0
2024-09-28 22:07:49,403 - INFO - file_cache is only supported with oauth2client<4.0.0
2024-09-28 22:07:49,408 - INFO - file_cache is only supported with oauth2client<4.0.0
2024-09-28 22:07:49,544 - WARNING - No hostname was supplied. Reverting to default 'localhost'
2024-09-30 12:05:30,445 - WARNING - Not Found: /favicon.ico
2024-09-30 13:23:17,032 - INFO - /app/actualizador/task.py changed, reloading.
2024-09-30 13:24:29,709 - INFO - /app/actualizador/task.py changed, reloading.
2024-09-30 13:25:30,977 - INFO - /app/actualizador/task.py changed, reloading.
2024-09-30 13:25:52,504 - INFO - file_cache is only supported with oauth2client<4.0.0
2024-09-30 13:25:52,515 - INFO - file_cache is only supported with oauth2client<4.0.0
2024-09-30 13:25:52,524 - INFO - file_cache is only supported with oauth2client<4.0.0
2024-09-30 13:25:52,640 - ERROR - Internal Server Error: /actualizar/
Traceback (most recent call last):
  File "/usr/local/lib/python3.10/site-packages/django/core/handlers/exception.py", line 55, in inner
    response = get_response(request)
  File "/usr/local/lib/python3.10/site-packages/django/core/handlers/base.py", line 197, in _get_response
    response = wrapped_callback(request, *callback_args, **callback_kwargs)
  File "/usr/local/lib/python3.10/site-packages/django/views/generic/base.py", line 84, in view
    return self.dispatch(request, *args, **kwargs)
  File "/usr/local/lib/python3.10/site-packages/django/views/generic/base.py", line 119, in dispatch
    return handler(request, *args, **kwargs)
  File "/app/actualizador/views.py", line 98, in get
    self.context = self.get_context_data()
  File "/app/actualizador/views.py", line 28, in get_context_data
    file = io.BytesIO()
NameError: name 'io' is not defined
2024-09-30 13:25:53,405 - WARNING - Not Found: /favicon.ico
2024-09-30 13:27:12,446 - INFO - /app/actualizador/views.py changed, reloading.
2024-09-30 13:27:23,261 - INFO - file_cache is only supported with oauth2client<4.0.0
2024-09-30 13:27:23,267 - INFO - file_cache is only supported with oauth2client<4.0.0
2024-09-30 13:27:23,274 - INFO - file_cache is only supported with oauth2client<4.0.0
2024-09-30 13:27:23,362 - ERROR - Internal Server Error: /actualizar/
Traceback (most recent call last):
  File "/usr/local/lib/python3.10/site-packages/django/core/handlers/exception.py", line 55, in inner
    response = get_response(request)
  File "/usr/local/lib/python3.10/site-packages/django/core/handlers/base.py", line 197, in _get_response
    response = wrapped_callback(request, *callback_args, **callback_kwargs)
  File "/usr/local/lib/python3.10/site-packages/django/views/generic/base.py", line 84, in view
    return self.dispatch(request, *args, **kwargs)
  File "/usr/local/lib/python3.10/site-packages/django/views/generic/base.py", line 119, in dispatch
    return handler(request, *args, **kwargs)
  File "/app/actualizador/views.py", line 99, in get
    self.context = self.get_context_data()
  File "/app/actualizador/views.py", line 30, in get_context_data
    downloader = MediaIoBaseDownload(file, request)
NameError: name 'MediaIoBaseDownload' is not defined
2024-09-30 13:27:23,888 - WARNING - Not Found: /favicon.ico
2024-09-30 13:27:55,788 - INFO - /app/actualizador/views.py changed, reloading.
2024-09-30 13:28:11,823 - INFO - file_cache is only supported with oauth2client<4.0.0
2024-09-30 13:28:11,828 - INFO - file_cache is only supported with oauth2client<4.0.0
2024-09-30 13:28:11,834 - INFO - file_cache is only supported with oauth2client<4.0.0
2024-09-30 13:28:12,063 - INFO - Refreshing credentials due to a 401 response. Attempt 1/2.
2024-09-30 13:28:38,216 - INFO - file_cache is only supported with oauth2client<4.0.0
2024-09-30 13:28:38,223 - INFO - file_cache is only supported with oauth2client<4.0.0
2024-09-30 13:28:38,236 - INFO - file_cache is only supported with oauth2client<4.0.0
2024-09-30 13:28:38,582 - INFO - Refreshing credentials due to a 401 response. Attempt 1/2.
2024-09-30 13:28:47,491 - WARNING - No hostname was supplied. Reverting to default 'localhost'
2024-09-30 13:37:36,438 - WARNING - Not Found: /favicon.ico
2024-09-30 13:37:56,251 - WARNING - Not Found: /favicon.ico
2024-09-30 13:38:15,742 - INFO - file_cache is only supported with oauth2client<4.0.0
2024-09-30 13:38:15,749 - INFO - file_cache is only supported with oauth2client<4.0.0
2024-09-30 13:38:15,758 - INFO - file_cache is only supported with oauth2client<4.0.0
2024-09-30 13:38:16,071 - INFO - Refreshing credentials due to a 401 response. Attempt 1/2.
2024-09-30 13:58:05,833 - INFO - /app/actualizador/views.py changed, reloading.
2024-09-30 13:58:51,452 - INFO - file_cache is only supported with oauth2client<4.0.0
2024-09-30 13:58:51,458 - INFO - file_cache is only supported with oauth2client<4.0.0
2024-09-30 13:58:51,466 - INFO - file_cache is only supported with oauth2client<4.0.0
2024-09-30 13:58:51,735 - INFO - Refreshing credentials due to a 401 response. Attempt 1/2.
2024-09-30 14:00:50,911 - INFO - /app/actualizador/views.py changed, reloading.
2024-09-30 14:00:58,045 - INFO - file_cache is only supported with oauth2client<4.0.0
2024-09-30 14:00:58,052 - INFO - file_cache is only supported with oauth2client<4.0.0
2024-09-30 14:00:58,063 - INFO - file_cache is only supported with oauth2client<4.0.0
2024-09-30 14:00:58,357 - INFO - Refreshing credentials due to a 401 response. Attempt 1/2.
2024-09-30 14:01:29,130 - INFO - /app/actualizador/views.py changed, reloading.
2024-09-30 14:01:32,927 - INFO - file_cache is only supported with oauth2client<4.0.0
2024-09-30 14:01:32,932 - INFO - file_cache is only supported with oauth2client<4.0.0
2024-09-30 14:01:32,941 - INFO - file_cache is only supported with oauth2client<4.0.0
2024-09-30 14:01:33,175 - INFO - Refreshing credentials due to a 401 response. Attempt 1/2.
2024-09-30 14:02:56,676 - INFO - file_cache is only supported with oauth2client<4.0.0
2024-09-30 14:02:56,683 - INFO - file_cache is only supported with oauth2client<4.0.0
2024-09-30 14:02:56,689 - INFO - file_cache is only supported with oauth2client<4.0.0
2024-09-30 14:02:56,917 - INFO - Refreshing credentials due to a 401 response. Attempt 1/2.
2024-09-30 14:03:04,010 - WARNING - No hostname was supplied. Reverting to default 'localhost'
2024-09-30 14:03:04,144 - ERROR - Internal Server Error: /actualizar/
Traceback (most recent call last):
  File "/usr/local/lib/python3.10/site-packages/django/core/handlers/exception.py", line 55, in inner
    response = get_response(request)
  File "/usr/local/lib/python3.10/site-packages/django/core/handlers/base.py", line 197, in _get_response
    response = wrapped_callback(request, *callback_args, **callback_kwargs)
  File "/usr/local/lib/python3.10/site-packages/django/views/generic/base.py", line 84, in view
    return self.dispatch(request, *args, **kwargs)
  File "/usr/local/lib/python3.10/site-packages/django/views/generic/base.py", line 119, in dispatch
    return handler(request, *args, **kwargs)
  File "/app/actualizador/views.py", line 148, in post
    planilla.proveedor = Proveedor.objects.get(id=proveedor[i])
NameError: name 'Proveedor' is not defined
2024-09-30 14:04:09,743 - INFO - /app/actualizador/views.py changed, reloading.
2024-09-30 14:04:26,453 - INFO - file_cache is only supported with oauth2client<4.0.0
2024-09-30 14:04:26,460 - INFO - file_cache is only supported with oauth2client<4.0.0
2024-09-30 14:04:26,467 - INFO - file_cache is only supported with oauth2client<4.0.0
2024-09-30 14:04:26,711 - INFO - Refreshing credentials due to a 401 response. Attempt 1/2.
2024-09-30 14:04:34,862 - WARNING - No hostname was supplied. Reverting to default 'localhost'
2024-09-30 14:09:59,337 - INFO - file_cache is only supported with oauth2client<4.0.0
2024-09-30 14:09:59,347 - INFO - file_cache is only supported with oauth2client<4.0.0
2024-09-30 14:09:59,359 - INFO - file_cache is only supported with oauth2client<4.0.0
2024-09-30 14:20:07,611 - INFO - /app/actualizador/views.py changed, reloading.
2024-09-30 14:20:46,225 - INFO - /app/actualizador/views.py changed, reloading.
2024-09-30 14:20:58,934 - INFO - file_cache is only supported with oauth2client<4.0.0
2024-09-30 14:20:58,942 - INFO - file_cache is only supported with oauth2client<4.0.0
2024-09-30 14:20:58,950 - INFO - file_cache is only supported with oauth2client<4.0.0
2024-09-30 14:20:59,135 - WARNING - No hostname was supplied. Reverting to default 'localhost'
2024-09-30 14:28:35,058 - INFO - file_cache is only supported with oauth2client<4.0.0
2024-09-30 14:28:35,069 - INFO - file_cache is only supported with oauth2client<4.0.0
2024-09-30 14:28:35,078 - INFO - file_cache is only supported with oauth2client<4.0.0
2024-09-30 14:28:35,257 - WARNING - No hostname was supplied. Reverting to default 'localhost'
2024-09-30 14:31:33,070 - WARNING - Not Found: /favicon.ico
2024-09-30 14:33:20,194 - INFO - file_cache is only supported with oauth2client<4.0.0
2024-09-30 14:33:20,199 - INFO - file_cache is only supported with oauth2client<4.0.0
2024-09-30 14:33:20,204 - INFO - file_cache is only supported with oauth2client<4.0.0
2024-09-30 14:33:24,683 - INFO - file_cache is only supported with oauth2client<4.0.0
2024-09-30 14:33:24,688 - INFO - file_cache is only supported with oauth2client<4.0.0
2024-09-30 14:33:24,692 - INFO - file_cache is only supported with oauth2client<4.0.0
2024-09-30 14:34:21,380 - INFO - /app/actualizador/task.py changed, reloading.
2024-09-30 14:35:06,910 - INFO - /app/actualizador/task.py changed, reloading.
2024-09-30 14:42:59,070 - INFO - file_cache is only supported with oauth2client<4.0.0
2024-09-30 14:42:59,076 - INFO - file_cache is only supported with oauth2client<4.0.0
2024-09-30 14:42:59,081 - INFO - file_cache is only supported with oauth2client<4.0.0
2024-09-30 14:54:18,236 - INFO - file_cache is only supported with oauth2client<4.0.0
2024-09-30 14:54:18,248 - INFO - file_cache is only supported with oauth2client<4.0.0
2024-09-30 14:54:18,254 - INFO - file_cache is only supported with oauth2client<4.0.0
2024-09-30 14:54:21,807 - INFO - file_cache is only supported with oauth2client<4.0.0
2024-09-30 14:54:21,814 - INFO - file_cache is only supported with oauth2client<4.0.0
2024-09-30 14:54:21,821 - INFO - file_cache is only supported with oauth2client<4.0.0
2024-09-30 14:54:21,989 - WARNING - No hostname was supplied. Reverting to default 'localhost'
2024-10-02 11:25:36,121 - WARNING - Not Found: /favicon.ico
2024-10-02 11:25:48,536 - WARNING - Not Found: /favicon.ico
2024-10-02 11:25:55,391 - INFO - file_cache is only supported with oauth2client<4.0.0
2024-10-02 11:25:55,399 - INFO - file_cache is only supported with oauth2client<4.0.0
2024-10-02 11:25:55,408 - INFO - file_cache is only supported with oauth2client<4.0.0
2024-10-02 11:25:58,255 - INFO - file_cache is only supported with oauth2client<4.0.0
2024-10-02 11:25:58,263 - INFO - file_cache is only supported with oauth2client<4.0.0
2024-10-02 11:25:58,270 - INFO - file_cache is only supported with oauth2client<4.0.0
2024-10-02 11:27:10,025 - INFO - file_cache is only supported with oauth2client<4.0.0
2024-10-02 11:27:10,034 - INFO - file_cache is only supported with oauth2client<4.0.0
2024-10-02 11:27:10,041 - INFO - file_cache is only supported with oauth2client<4.0.0
2024-10-02 11:27:10,339 - INFO - Refreshing credentials due to a 401 response. Attempt 1/2.
2024-10-02 11:27:43,123 - INFO - file_cache is only supported with oauth2client<4.0.0
2024-10-02 11:27:43,130 - INFO - file_cache is only supported with oauth2client<4.0.0
2024-10-02 11:27:43,147 - INFO - file_cache is only supported with oauth2client<4.0.0
2024-10-02 11:27:43,413 - INFO - Refreshing credentials due to a 401 response. Attempt 1/2.
2024-10-02 11:29:10,485 - INFO - file_cache is only supported with oauth2client<4.0.0
2024-10-02 11:29:10,500 - INFO - file_cache is only supported with oauth2client<4.0.0
2024-10-02 11:29:10,508 - INFO - file_cache is only supported with oauth2client<4.0.0
2024-10-02 11:29:10,761 - INFO - Refreshing credentials due to a 401 response. Attempt 1/2.
2024-10-02 11:29:24,237 - INFO - file_cache is only supported with oauth2client<4.0.0
2024-10-02 11:29:24,246 - INFO - file_cache is only supported with oauth2client<4.0.0
2024-10-02 11:29:24,252 - INFO - file_cache is only supported with oauth2client<4.0.0
2024-10-02 11:29:24,499 - INFO - Refreshing credentials due to a 401 response. Attempt 1/2.
2024-10-02 11:29:27,356 - INFO - file_cache is only supported with oauth2client<4.0.0
2024-10-02 11:29:27,369 - INFO - file_cache is only supported with oauth2client<4.0.0
2024-10-02 11:29:27,374 - INFO - file_cache is only supported with oauth2client<4.0.0
2024-10-02 11:29:27,618 - INFO - Refreshing credentials due to a 401 response. Attempt 1/2.
2024-10-02 11:29:42,921 - INFO - file_cache is only supported with oauth2client<4.0.0
2024-10-02 11:29:42,927 - INFO - file_cache is only supported with oauth2client<4.0.0
2024-10-02 11:29:42,932 - INFO - file_cache is only supported with oauth2client<4.0.0
2024-10-02 11:29:43,183 - INFO - Refreshing credentials due to a 401 response. Attempt 1/2.
2024-10-02 13:19:08,187 - INFO - file_cache is only supported with oauth2client<4.0.0
2024-10-02 13:19:08,200 - INFO - file_cache is only supported with oauth2client<4.0.0
2024-10-02 13:19:08,211 - INFO - file_cache is only supported with oauth2client<4.0.0
2024-10-02 13:19:08,478 - INFO - Refreshing credentials due to a 401 response. Attempt 1/2.
2024-10-02 14:07:58,894 - INFO - file_cache is only supported with oauth2client<4.0.0
2024-10-02 14:07:58,902 - INFO - file_cache is only supported with oauth2client<4.0.0
2024-10-02 14:07:58,908 - INFO - file_cache is only supported with oauth2client<4.0.0
2024-10-02 14:07:59,172 - INFO - Refreshing credentials due to a 401 response. Attempt 1/2.
2024-10-02 14:08:20,142 - INFO - file_cache is only supported with oauth2client<4.0.0
2024-10-02 14:08:20,147 - INFO - file_cache is only supported with oauth2client<4.0.0
2024-10-02 14:08:20,153 - INFO - file_cache is only supported with oauth2client<4.0.0
2024-10-02 14:08:45,520 - ERROR - Internal Server Error: /actualizar/
Traceback (most recent call last):
  File "/usr/local/lib/python3.10/site-packages/django/db/models/fields/related_descriptors.py", line 187, in __get__
    rel_obj = self.field.get_cached_value(instance)
  File "/usr/local/lib/python3.10/site-packages/django/db/models/fields/mixins.py", line 15, in get_cached_value
    return instance._state.fields_cache[cache_name]
KeyError: 'proveedor'

During handling of the above exception, another exception occurred:

Traceback (most recent call last):
  File "/usr/local/lib/python3.10/site-packages/django/db/backends/utils.py", line 89, in _execute
    return self.cursor.execute(sql, params)
  File "/usr/local/lib/python3.10/site-packages/django/db/backends/sqlite3/base.py", line 477, in execute
    return Database.Cursor.execute(self, query, params)
sqlite3.OperationalError: database is locked

The above exception was the direct cause of the following exception:

Traceback (most recent call last):
  File "/usr/local/lib/python3.10/site-packages/django/core/handlers/exception.py", line 55, in inner
    response = get_response(request)
  File "/usr/local/lib/python3.10/site-packages/django/core/handlers/base.py", line 197, in _get_response
    response = wrapped_callback(request, *callback_args, **callback_kwargs)
  File "/usr/local/lib/python3.10/site-packages/django/views/generic/base.py", line 84, in view
    return self.dispatch(request, *args, **kwargs)
  File "/usr/local/lib/python3.10/site-packages/django/views/generic/base.py", line 119, in dispatch
    return handler(request, *args, **kwargs)
  File "/app/actualizador/views.py", line 165, in post
    print("seleccion: ",self.context['seleccion_planillas'])
  File "/usr/local/lib/python3.10/site-packages/django/db/models/query.py", line 299, in __repr__
    return "<%s %r>" % (self.__class__.__name__, data)
  File "/usr/local/lib/python3.10/site-packages/django/db/models/base.py", line 580, in __repr__
    return "<%s: %s>" % (self.__class__.__name__, self)
  File "/app/bdd/models.py", line 450, in __str__
    text = "{} - {}".format(self.proveedor, self.fecha)
  File "/usr/local/lib/python3.10/site-packages/django/db/models/fields/related_descriptors.py", line 205, in __get__
    rel_obj = self.get_object(instance)
  File "/usr/local/lib/python3.10/site-packages/django/db/models/fields/related_descriptors.py", line 168, in get_object
    return qs.get(self.field.get_reverse_related_filter(instance))
  File "/usr/local/lib/python3.10/site-packages/django/db/models/query.py", line 492, in get
    num = len(clone)
  File "/usr/local/lib/python3.10/site-packages/django/db/models/query.py", line 302, in __len__
    self._fetch_all()
  File "/usr/local/lib/python3.10/site-packages/django/db/models/query.py", line 1507, in _fetch_all
    self._result_cache = list(self._iterable_class(self))
  File "/usr/local/lib/python3.10/site-packages/django/db/models/query.py", line 57, in __iter__
    results = compiler.execute_sql(
  File "/usr/local/lib/python3.10/site-packages/django/db/models/sql/compiler.py", line 1361, in execute_sql
    cursor.execute(sql, params)
  File "/usr/local/lib/python3.10/site-packages/django/db/backends/utils.py", line 103, in execute
    return super().execute(sql, params)
  File "/usr/local/lib/python3.10/site-packages/django/db/backends/utils.py", line 67, in execute
    return self._execute_with_wrappers(
  File "/usr/local/lib/python3.10/site-packages/django/db/backends/utils.py", line 80, in _execute_with_wrappers
    return executor(sql, params, many, context)
  File "/usr/local/lib/python3.10/site-packages/django/db/backends/utils.py", line 84, in _execute
    with self.db.wrap_database_errors:
  File "/usr/local/lib/python3.10/site-packages/django/db/utils.py", line 91, in __exit__
    raise dj_exc_value.with_traceback(traceback) from exc_value
  File "/usr/local/lib/python3.10/site-packages/django/db/backends/utils.py", line 89, in _execute
    return self.cursor.execute(sql, params)
  File "/usr/local/lib/python3.10/site-packages/django/db/backends/sqlite3/base.py", line 477, in execute
    return Database.Cursor.execute(self, query, params)
django.db.utils.OperationalError: database is locked
2024-10-02 14:08:45,940 - WARNING - Not Found: /favicon.ico
2024-10-02 14:19:09,104 - INFO - file_cache is only supported with oauth2client<4.0.0
2024-10-02 14:19:09,112 - INFO - file_cache is only supported with oauth2client<4.0.0
2024-10-02 14:19:09,118 - INFO - file_cache is only supported with oauth2client<4.0.0
2024-10-02 14:19:30,865 - INFO - file_cache is only supported with oauth2client<4.0.0
2024-10-02 14:19:30,872 - INFO - file_cache is only supported with oauth2client<4.0.0
2024-10-02 14:19:30,881 - INFO - file_cache is only supported with oauth2client<4.0.0
2024-10-02 14:59:45,047 - INFO - file_cache is only supported with oauth2client<4.0.0
2024-10-02 14:59:45,055 - INFO - file_cache is only supported with oauth2client<4.0.0
2024-10-02 14:59:45,085 - INFO - file_cache is only supported with oauth2client<4.0.0
2024-10-02 14:59:54,291 - INFO - file_cache is only supported with oauth2client<4.0.0
2024-10-02 14:59:54,300 - INFO - file_cache is only supported with oauth2client<4.0.0
2024-10-02 14:59:54,306 - INFO - file_cache is only supported with oauth2client<4.0.0
2024-10-02 15:01:34,935 - INFO - file_cache is only supported with oauth2client<4.0.0
2024-10-02 15:01:34,943 - INFO - file_cache is only supported with oauth2client<4.0.0
2024-10-02 15:01:34,950 - INFO - file_cache is only supported with oauth2client<4.0.0
2024-10-02 15:01:35,265 - WARNING - No hostname was supplied. Reverting to default 'localhost'
2024-10-02 15:01:41,506 - ERROR - Internal Server Error: /actualizar/
Traceback (most recent call last):
  File "/usr/local/lib/python3.10/site-packages/kombu/utils/functional.py", line 32, in __call__
    return self.__value__
AttributeError: 'ChannelPromise' object has no attribute '__value__'

During handling of the above exception, another exception occurred:

Traceback (most recent call last):
  File "/usr/local/lib/python3.10/site-packages/kombu/connection.py", line 472, in _reraise_as_library_errors
    yield
  File "/usr/local/lib/python3.10/site-packages/kombu/connection.py", line 459, in _ensure_connection
    return retry_over_time(
  File "/usr/local/lib/python3.10/site-packages/kombu/utils/functional.py", line 318, in retry_over_time
    return fun(*args, **kwargs)
  File "/usr/local/lib/python3.10/site-packages/kombu/connection.py", line 934, in _connection_factory
    self._connection = self._establish_connection()
  File "/usr/local/lib/python3.10/site-packages/kombu/connection.py", line 860, in _establish_connection
    conn = self.transport.establish_connection()
  File "/usr/local/lib/python3.10/site-packages/kombu/transport/pyamqp.py", line 203, in establish_connection
    conn.connect()
  File "/usr/local/lib/python3.10/site-packages/amqp/connection.py", line 324, in connect
    self.transport.connect()
  File "/usr/local/lib/python3.10/site-packages/amqp/transport.py", line 129, in connect
    self._connect(self.host, self.port, self.connect_timeout)
  File "/usr/local/lib/python3.10/site-packages/amqp/transport.py", line 184, in _connect
    self.sock.connect(sa)
ConnectionRefusedError: [Errno 111] Connection refused

The above exception was the direct cause of the following exception:

Traceback (most recent call last):
  File "/usr/local/lib/python3.10/site-packages/django/core/handlers/exception.py", line 55, in inner
    response = get_response(request)
  File "/usr/local/lib/python3.10/site-packages/django/core/handlers/base.py", line 197, in _get_response
    response = wrapped_callback(request, *callback_args, **callback_kwargs)
  File "/usr/local/lib/python3.10/site-packages/django/views/generic/base.py", line 84, in view
    return self.dispatch(request, *args, **kwargs)
  File "/usr/local/lib/python3.10/site-packages/django/views/generic/base.py", line 119, in dispatch
    return handler(request, *args, **kwargs)
  File "/app/actualizador/views.py", line 121, in post
    task = recolectar_procesar.delay()  # Ejecuta la tarea de Celery
  File "/usr/local/lib/python3.10/site-packages/celery/app/task.py", line 444, in delay
    return self.apply_async(args, kwargs)
  File "/usr/local/lib/python3.10/site-packages/celery/app/task.py", line 594, in apply_async
    return app.send_task(
  File "/usr/local/lib/python3.10/site-packages/celery/app/base.py", line 801, in send_task
    amqp.send_task_message(P, name, message, **options)
  File "/usr/local/lib/python3.10/site-packages/celery/app/amqp.py", line 518, in send_task_message
    ret = producer.publish(
  File "/usr/local/lib/python3.10/site-packages/kombu/messaging.py", line 186, in publish
    return _publish(
  File "/usr/local/lib/python3.10/site-packages/kombu/connection.py", line 556, in _ensured
    return fun(*args, **kwargs)
  File "/usr/local/lib/python3.10/site-packages/kombu/messaging.py", line 195, in _publish
    channel = self.channel
  File "/usr/local/lib/python3.10/site-packages/kombu/messaging.py", line 218, in _get_channel
    channel = self._channel = channel()
  File "/usr/local/lib/python3.10/site-packages/kombu/utils/functional.py", line 34, in __call__
    value = self.__value__ = self.__contract__()
  File "/usr/local/lib/python3.10/site-packages/kombu/messaging.py", line 234, in <lambda>
    channel = ChannelPromise(lambda: connection.default_channel)
  File "/usr/local/lib/python3.10/site-packages/kombu/connection.py", line 953, in default_channel
    self._ensure_connection(**conn_opts)
  File "/usr/local/lib/python3.10/site-packages/kombu/connection.py", line 458, in _ensure_connection
    with ctx():
  File "/usr/local/lib/python3.10/contextlib.py", line 153, in __exit__
    self.gen.throw(typ, value, traceback)
  File "/usr/local/lib/python3.10/site-packages/kombu/connection.py", line 476, in _reraise_as_library_errors
    raise ConnectionError(str(exc)) from exc
kombu.exceptions.OperationalError: [Errno 111] Connection refused
2024-10-02 15:24:11,258 - INFO - file_cache is only supported with oauth2client<4.0.0
2024-10-02 15:24:11,264 - INFO - file_cache is only supported with oauth2client<4.0.0
2024-10-02 15:24:11,271 - INFO - file_cache is only supported with oauth2client<4.0.0
2024-10-02 15:24:21,863 - INFO - file_cache is only supported with oauth2client<4.0.0
2024-10-02 15:24:21,869 - INFO - file_cache is only supported with oauth2client<4.0.0
2024-10-02 15:24:21,874 - INFO - file_cache is only supported with oauth2client<4.0.0
2024-10-02 15:24:28,171 - ERROR - Internal Server Error: /actualizar/
Traceback (most recent call last):
  File "/usr/local/lib/python3.10/site-packages/kombu/utils/functional.py", line 32, in __call__
    return self.__value__
AttributeError: 'ChannelPromise' object has no attribute '__value__'

During handling of the above exception, another exception occurred:

Traceback (most recent call last):
  File "/usr/local/lib/python3.10/site-packages/kombu/connection.py", line 472, in _reraise_as_library_errors
    yield
  File "/usr/local/lib/python3.10/site-packages/kombu/connection.py", line 459, in _ensure_connection
    return retry_over_time(
  File "/usr/local/lib/python3.10/site-packages/kombu/utils/functional.py", line 318, in retry_over_time
    return fun(*args, **kwargs)
  File "/usr/local/lib/python3.10/site-packages/kombu/connection.py", line 934, in _connection_factory
    self._connection = self._establish_connection()
  File "/usr/local/lib/python3.10/site-packages/kombu/connection.py", line 860, in _establish_connection
    conn = self.transport.establish_connection()
  File "/usr/local/lib/python3.10/site-packages/kombu/transport/pyamqp.py", line 203, in establish_connection
    conn.connect()
  File "/usr/local/lib/python3.10/site-packages/amqp/connection.py", line 324, in connect
    self.transport.connect()
  File "/usr/local/lib/python3.10/site-packages/amqp/transport.py", line 129, in connect
    self._connect(self.host, self.port, self.connect_timeout)
  File "/usr/local/lib/python3.10/site-packages/amqp/transport.py", line 184, in _connect
    self.sock.connect(sa)
ConnectionRefusedError: [Errno 111] Connection refused

The above exception was the direct cause of the following exception:

Traceback (most recent call last):
  File "/usr/local/lib/python3.10/site-packages/django/core/handlers/exception.py", line 55, in inner
    response = get_response(request)
  File "/usr/local/lib/python3.10/site-packages/django/core/handlers/base.py", line 197, in _get_response
    response = wrapped_callback(request, *callback_args, **callback_kwargs)
  File "/usr/local/lib/python3.10/site-packages/django/views/generic/base.py", line 84, in view
    return self.dispatch(request, *args, **kwargs)
  File "/usr/local/lib/python3.10/site-packages/django/views/generic/base.py", line 119, in dispatch
    return handler(request, *args, **kwargs)
  File "/app/actualizador/views.py", line 121, in post
    task = recolectar_procesar.delay()  # Ejecuta la tarea de Celery
  File "/usr/local/lib/python3.10/site-packages/celery/app/task.py", line 444, in delay
    return self.apply_async(args, kwargs)
  File "/usr/local/lib/python3.10/site-packages/celery/app/task.py", line 594, in apply_async
    return app.send_task(
  File "/usr/local/lib/python3.10/site-packages/celery/app/base.py", line 801, in send_task
    amqp.send_task_message(P, name, message, **options)
  File "/usr/local/lib/python3.10/site-packages/celery/app/amqp.py", line 518, in send_task_message
    ret = producer.publish(
  File "/usr/local/lib/python3.10/site-packages/kombu/messaging.py", line 186, in publish
    return _publish(
  File "/usr/local/lib/python3.10/site-packages/kombu/connection.py", line 556, in _ensured
    return fun(*args, **kwargs)
  File "/usr/local/lib/python3.10/site-packages/kombu/messaging.py", line 195, in _publish
    channel = self.channel
  File "/usr/local/lib/python3.10/site-packages/kombu/messaging.py", line 218, in _get_channel
    channel = self._channel = channel()
  File "/usr/local/lib/python3.10/site-packages/kombu/utils/functional.py", line 34, in __call__
    value = self.__value__ = self.__contract__()
  File "/usr/local/lib/python3.10/site-packages/kombu/messaging.py", line 234, in <lambda>
    channel = ChannelPromise(lambda: connection.default_channel)
  File "/usr/local/lib/python3.10/site-packages/kombu/connection.py", line 953, in default_channel
    self._ensure_connection(**conn_opts)
  File "/usr/local/lib/python3.10/site-packages/kombu/connection.py", line 458, in _ensure_connection
    with ctx():
  File "/usr/local/lib/python3.10/contextlib.py", line 153, in __exit__
    self.gen.throw(typ, value, traceback)
  File "/usr/local/lib/python3.10/site-packages/kombu/connection.py", line 476, in _reraise_as_library_errors
    raise ConnectionError(str(exc)) from exc
kombu.exceptions.OperationalError: [Errno 111] Connection refused
2024-10-02 16:38:27,425 - INFO - file_cache is only supported with oauth2client<4.0.0
2024-10-02 16:38:27,432 - INFO - file_cache is only supported with oauth2client<4.0.0
2024-10-02 16:38:27,439 - INFO - file_cache is only supported with oauth2client<4.0.0
2024-10-02 16:38:30,640 - INFO - file_cache is only supported with oauth2client<4.0.0
2024-10-02 16:38:30,647 - INFO - file_cache is only supported with oauth2client<4.0.0
2024-10-02 16:38:30,654 - INFO - file_cache is only supported with oauth2client<4.0.0
2024-10-02 16:38:30,817 - WARNING - No hostname was supplied. Reverting to default 'localhost'
2024-10-02 16:38:36,988 - ERROR - Internal Server Error: /actualizar/
Traceback (most recent call last):
  File "/usr/local/lib/python3.10/site-packages/kombu/utils/functional.py", line 32, in __call__
    return self.__value__
AttributeError: 'ChannelPromise' object has no attribute '__value__'

During handling of the above exception, another exception occurred:

Traceback (most recent call last):
  File "/usr/local/lib/python3.10/site-packages/kombu/connection.py", line 472, in _reraise_as_library_errors
    yield
  File "/usr/local/lib/python3.10/site-packages/kombu/connection.py", line 459, in _ensure_connection
    return retry_over_time(
  File "/usr/local/lib/python3.10/site-packages/kombu/utils/functional.py", line 318, in retry_over_time
    return fun(*args, **kwargs)
  File "/usr/local/lib/python3.10/site-packages/kombu/connection.py", line 934, in _connection_factory
    self._connection = self._establish_connection()
  File "/usr/local/lib/python3.10/site-packages/kombu/connection.py", line 860, in _establish_connection
    conn = self.transport.establish_connection()
  File "/usr/local/lib/python3.10/site-packages/kombu/transport/pyamqp.py", line 203, in establish_connection
    conn.connect()
  File "/usr/local/lib/python3.10/site-packages/amqp/connection.py", line 324, in connect
    self.transport.connect()
  File "/usr/local/lib/python3.10/site-packages/amqp/transport.py", line 129, in connect
    self._connect(self.host, self.port, self.connect_timeout)
  File "/usr/local/lib/python3.10/site-packages/amqp/transport.py", line 184, in _connect
    self.sock.connect(sa)
ConnectionRefusedError: [Errno 111] Connection refused

The above exception was the direct cause of the following exception:

Traceback (most recent call last):
  File "/usr/local/lib/python3.10/site-packages/django/core/handlers/exception.py", line 55, in inner
    response = get_response(request)
  File "/usr/local/lib/python3.10/site-packages/django/core/handlers/base.py", line 197, in _get_response
    response = wrapped_callback(request, *callback_args, **callback_kwargs)
  File "/usr/local/lib/python3.10/site-packages/django/views/generic/base.py", line 84, in view
    return self.dispatch(request, *args, **kwargs)
  File "/usr/local/lib/python3.10/site-packages/django/views/generic/base.py", line 119, in dispatch
    return handler(request, *args, **kwargs)
  File "/app/actualizador/views.py", line 121, in post
    task = recolectar_procesar.delay()  # Ejecuta la tarea de Celery
  File "/usr/local/lib/python3.10/site-packages/celery/app/task.py", line 444, in delay
    return self.apply_async(args, kwargs)
  File "/usr/local/lib/python3.10/site-packages/celery/app/task.py", line 594, in apply_async
    return app.send_task(
  File "/usr/local/lib/python3.10/site-packages/celery/app/base.py", line 801, in send_task
    amqp.send_task_message(P, name, message, **options)
  File "/usr/local/lib/python3.10/site-packages/celery/app/amqp.py", line 518, in send_task_message
    ret = producer.publish(
  File "/usr/local/lib/python3.10/site-packages/kombu/messaging.py", line 186, in publish
    return _publish(
  File "/usr/local/lib/python3.10/site-packages/kombu/connection.py", line 556, in _ensured
    return fun(*args, **kwargs)
  File "/usr/local/lib/python3.10/site-packages/kombu/messaging.py", line 195, in _publish
    channel = self.channel
  File "/usr/local/lib/python3.10/site-packages/kombu/messaging.py", line 218, in _get_channel
    channel = self._channel = channel()
  File "/usr/local/lib/python3.10/site-packages/kombu/utils/functional.py", line 34, in __call__
    value = self.__value__ = self.__contract__()
  File "/usr/local/lib/python3.10/site-packages/kombu/messaging.py", line 234, in <lambda>
    channel = ChannelPromise(lambda: connection.default_channel)
  File "/usr/local/lib/python3.10/site-packages/kombu/connection.py", line 953, in default_channel
    self._ensure_connection(**conn_opts)
  File "/usr/local/lib/python3.10/site-packages/kombu/connection.py", line 458, in _ensure_connection
    with ctx():
  File "/usr/local/lib/python3.10/contextlib.py", line 153, in __exit__
    self.gen.throw(typ, value, traceback)
  File "/usr/local/lib/python3.10/site-packages/kombu/connection.py", line 476, in _reraise_as_library_errors
    raise ConnectionError(str(exc)) from exc
kombu.exceptions.OperationalError: [Errno 111] Connection refused
2024-10-02 16:45:35,109 - INFO - file_cache is only supported with oauth2client<4.0.0
2024-10-02 16:45:35,115 - INFO - file_cache is only supported with oauth2client<4.0.0
2024-10-02 16:45:35,122 - INFO - file_cache is only supported with oauth2client<4.0.0
2024-10-02 16:45:39,138 - INFO - file_cache is only supported with oauth2client<4.0.0
2024-10-02 16:45:39,145 - INFO - file_cache is only supported with oauth2client<4.0.0
2024-10-02 16:45:39,151 - INFO - file_cache is only supported with oauth2client<4.0.0
2024-10-02 16:45:45,438 - ERROR - Internal Server Error: /actualizar/
Traceback (most recent call last):
  File "/usr/local/lib/python3.10/site-packages/kombu/utils/functional.py", line 32, in __call__
    return self.__value__
AttributeError: 'ChannelPromise' object has no attribute '__value__'

During handling of the above exception, another exception occurred:

Traceback (most recent call last):
  File "/usr/local/lib/python3.10/site-packages/kombu/connection.py", line 472, in _reraise_as_library_errors
    yield
  File "/usr/local/lib/python3.10/site-packages/kombu/connection.py", line 459, in _ensure_connection
    return retry_over_time(
  File "/usr/local/lib/python3.10/site-packages/kombu/utils/functional.py", line 318, in retry_over_time
    return fun(*args, **kwargs)
  File "/usr/local/lib/python3.10/site-packages/kombu/connection.py", line 934, in _connection_factory
    self._connection = self._establish_connection()
  File "/usr/local/lib/python3.10/site-packages/kombu/connection.py", line 860, in _establish_connection
    conn = self.transport.establish_connection()
  File "/usr/local/lib/python3.10/site-packages/kombu/transport/pyamqp.py", line 203, in establish_connection
    conn.connect()
  File "/usr/local/lib/python3.10/site-packages/amqp/connection.py", line 324, in connect
    self.transport.connect()
  File "/usr/local/lib/python3.10/site-packages/amqp/transport.py", line 129, in connect
    self._connect(self.host, self.port, self.connect_timeout)
  File "/usr/local/lib/python3.10/site-packages/amqp/transport.py", line 184, in _connect
    self.sock.connect(sa)
ConnectionRefusedError: [Errno 111] Connection refused

The above exception was the direct cause of the following exception:

Traceback (most recent call last):
  File "/usr/local/lib/python3.10/site-packages/django/core/handlers/exception.py", line 55, in inner
    response = get_response(request)
  File "/usr/local/lib/python3.10/site-packages/django/core/handlers/base.py", line 197, in _get_response
    response = wrapped_callback(request, *callback_args, **callback_kwargs)
  File "/usr/local/lib/python3.10/site-packages/django/views/generic/base.py", line 84, in view
    return self.dispatch(request, *args, **kwargs)
  File "/usr/local/lib/python3.10/site-packages/django/views/generic/base.py", line 119, in dispatch
    return handler(request, *args, **kwargs)
  File "/app/actualizador/views.py", line 121, in post
    task = recolectar_procesar.delay()  # Ejecuta la tarea de Celery
  File "/usr/local/lib/python3.10/site-packages/celery/app/task.py", line 444, in delay
    return self.apply_async(args, kwargs)
  File "/usr/local/lib/python3.10/site-packages/celery/app/task.py", line 594, in apply_async
    return app.send_task(
  File "/usr/local/lib/python3.10/site-packages/celery/app/base.py", line 801, in send_task
    amqp.send_task_message(P, name, message, **options)
  File "/usr/local/lib/python3.10/site-packages/celery/app/amqp.py", line 518, in send_task_message
    ret = producer.publish(
  File "/usr/local/lib/python3.10/site-packages/kombu/messaging.py", line 186, in publish
    return _publish(
  File "/usr/local/lib/python3.10/site-packages/kombu/connection.py", line 556, in _ensured
    return fun(*args, **kwargs)
  File "/usr/local/lib/python3.10/site-packages/kombu/messaging.py", line 195, in _publish
    channel = self.channel
  File "/usr/local/lib/python3.10/site-packages/kombu/messaging.py", line 218, in _get_channel
    channel = self._channel = channel()
  File "/usr/local/lib/python3.10/site-packages/kombu/utils/functional.py", line 34, in __call__
    value = self.__value__ = self.__contract__()
  File "/usr/local/lib/python3.10/site-packages/kombu/messaging.py", line 234, in <lambda>
    channel = ChannelPromise(lambda: connection.default_channel)
  File "/usr/local/lib/python3.10/site-packages/kombu/connection.py", line 953, in default_channel
    self._ensure_connection(**conn_opts)
  File "/usr/local/lib/python3.10/site-packages/kombu/connection.py", line 458, in _ensure_connection
    with ctx():
  File "/usr/local/lib/python3.10/contextlib.py", line 153, in __exit__
    self.gen.throw(typ, value, traceback)
  File "/usr/local/lib/python3.10/site-packages/kombu/connection.py", line 476, in _reraise_as_library_errors
    raise ConnectionError(str(exc)) from exc
kombu.exceptions.OperationalError: [Errno 111] Connection refused
2024-10-02 16:47:34,923 - INFO - file_cache is only supported with oauth2client<4.0.0
2024-10-02 16:47:34,929 - INFO - file_cache is only supported with oauth2client<4.0.0
2024-10-02 16:47:34,940 - INFO - file_cache is only supported with oauth2client<4.0.0
2024-10-02 16:47:39,214 - INFO - file_cache is only supported with oauth2client<4.0.0
2024-10-02 16:47:39,220 - INFO - file_cache is only supported with oauth2client<4.0.0
2024-10-02 16:47:39,227 - INFO - file_cache is only supported with oauth2client<4.0.0
2024-10-02 16:47:45,509 - ERROR - Internal Server Error: /actualizar/
Traceback (most recent call last):
  File "/usr/local/lib/python3.10/site-packages/kombu/utils/functional.py", line 32, in __call__
    return self.__value__
AttributeError: 'ChannelPromise' object has no attribute '__value__'

During handling of the above exception, another exception occurred:

Traceback (most recent call last):
  File "/usr/local/lib/python3.10/site-packages/kombu/connection.py", line 472, in _reraise_as_library_errors
    yield
  File "/usr/local/lib/python3.10/site-packages/kombu/connection.py", line 459, in _ensure_connection
    return retry_over_time(
  File "/usr/local/lib/python3.10/site-packages/kombu/utils/functional.py", line 318, in retry_over_time
    return fun(*args, **kwargs)
  File "/usr/local/lib/python3.10/site-packages/kombu/connection.py", line 934, in _connection_factory
    self._connection = self._establish_connection()
  File "/usr/local/lib/python3.10/site-packages/kombu/connection.py", line 860, in _establish_connection
    conn = self.transport.establish_connection()
  File "/usr/local/lib/python3.10/site-packages/kombu/transport/pyamqp.py", line 203, in establish_connection
    conn.connect()
  File "/usr/local/lib/python3.10/site-packages/amqp/connection.py", line 324, in connect
    self.transport.connect()
  File "/usr/local/lib/python3.10/site-packages/amqp/transport.py", line 129, in connect
    self._connect(self.host, self.port, self.connect_timeout)
  File "/usr/local/lib/python3.10/site-packages/amqp/transport.py", line 184, in _connect
    self.sock.connect(sa)
ConnectionRefusedError: [Errno 111] Connection refused

The above exception was the direct cause of the following exception:

Traceback (most recent call last):
  File "/usr/local/lib/python3.10/site-packages/django/core/handlers/exception.py", line 55, in inner
    response = get_response(request)
  File "/usr/local/lib/python3.10/site-packages/django/core/handlers/base.py", line 197, in _get_response
    response = wrapped_callback(request, *callback_args, **callback_kwargs)
  File "/usr/local/lib/python3.10/site-packages/django/views/generic/base.py", line 84, in view
    return self.dispatch(request, *args, **kwargs)
  File "/usr/local/lib/python3.10/site-packages/django/views/generic/base.py", line 119, in dispatch
    return handler(request, *args, **kwargs)
  File "/app/actualizador/views.py", line 121, in post
    task = recolectar_procesar.delay()  # Ejecuta la tarea de Celery
  File "/usr/local/lib/python3.10/site-packages/celery/app/task.py", line 444, in delay
    return self.apply_async(args, kwargs)
  File "/usr/local/lib/python3.10/site-packages/celery/app/task.py", line 594, in apply_async
    return app.send_task(
  File "/usr/local/lib/python3.10/site-packages/celery/app/base.py", line 801, in send_task
    amqp.send_task_message(P, name, message, **options)
  File "/usr/local/lib/python3.10/site-packages/celery/app/amqp.py", line 518, in send_task_message
    ret = producer.publish(
  File "/usr/local/lib/python3.10/site-packages/kombu/messaging.py", line 186, in publish
    return _publish(
  File "/usr/local/lib/python3.10/site-packages/kombu/connection.py", line 556, in _ensured
    return fun(*args, **kwargs)
  File "/usr/local/lib/python3.10/site-packages/kombu/messaging.py", line 195, in _publish
    channel = self.channel
  File "/usr/local/lib/python3.10/site-packages/kombu/messaging.py", line 218, in _get_channel
    channel = self._channel = channel()
  File "/usr/local/lib/python3.10/site-packages/kombu/utils/functional.py", line 34, in __call__
    value = self.__value__ = self.__contract__()
  File "/usr/local/lib/python3.10/site-packages/kombu/messaging.py", line 234, in <lambda>
    channel = ChannelPromise(lambda: connection.default_channel)
  File "/usr/local/lib/python3.10/site-packages/kombu/connection.py", line 953, in default_channel
    self._ensure_connection(**conn_opts)
  File "/usr/local/lib/python3.10/site-packages/kombu/connection.py", line 458, in _ensure_connection
    with ctx():
  File "/usr/local/lib/python3.10/contextlib.py", line 153, in __exit__
    self.gen.throw(typ, value, traceback)
  File "/usr/local/lib/python3.10/site-packages/kombu/connection.py", line 476, in _reraise_as_library_errors
    raise ConnectionError(str(exc)) from exc
kombu.exceptions.OperationalError: [Errno 111] Connection refused
2024-10-02 16:54:26,746 - INFO - file_cache is only supported with oauth2client<4.0.0
2024-10-02 16:54:26,754 - INFO - file_cache is only supported with oauth2client<4.0.0
2024-10-02 16:54:26,760 - INFO - file_cache is only supported with oauth2client<4.0.0
2024-10-02 16:54:29,872 - INFO - file_cache is only supported with oauth2client<4.0.0
2024-10-02 16:54:29,878 - INFO - file_cache is only supported with oauth2client<4.0.0
2024-10-02 16:54:29,884 - INFO - file_cache is only supported with oauth2client<4.0.0
2024-10-02 16:54:30,062 - WARNING - No hostname was supplied. Reverting to default 'localhost'
2024-10-02 16:54:36,248 - ERROR - Internal Server Error: /actualizar/
Traceback (most recent call last):
  File "/usr/local/lib/python3.10/site-packages/kombu/utils/functional.py", line 32, in __call__
    return self.__value__
AttributeError: 'ChannelPromise' object has no attribute '__value__'

During handling of the above exception, another exception occurred:

Traceback (most recent call last):
  File "/usr/local/lib/python3.10/site-packages/kombu/connection.py", line 472, in _reraise_as_library_errors
    yield
  File "/usr/local/lib/python3.10/site-packages/kombu/connection.py", line 459, in _ensure_connection
    return retry_over_time(
  File "/usr/local/lib/python3.10/site-packages/kombu/utils/functional.py", line 318, in retry_over_time
    return fun(*args, **kwargs)
  File "/usr/local/lib/python3.10/site-packages/kombu/connection.py", line 934, in _connection_factory
    self._connection = self._establish_connection()
  File "/usr/local/lib/python3.10/site-packages/kombu/connection.py", line 860, in _establish_connection
    conn = self.transport.establish_connection()
  File "/usr/local/lib/python3.10/site-packages/kombu/transport/pyamqp.py", line 203, in establish_connection
    conn.connect()
  File "/usr/local/lib/python3.10/site-packages/amqp/connection.py", line 324, in connect
    self.transport.connect()
  File "/usr/local/lib/python3.10/site-packages/amqp/transport.py", line 129, in connect
    self._connect(self.host, self.port, self.connect_timeout)
  File "/usr/local/lib/python3.10/site-packages/amqp/transport.py", line 184, in _connect
    self.sock.connect(sa)
ConnectionRefusedError: [Errno 111] Connection refused

The above exception was the direct cause of the following exception:

Traceback (most recent call last):
  File "/usr/local/lib/python3.10/site-packages/django/core/handlers/exception.py", line 55, in inner
    response = get_response(request)
  File "/usr/local/lib/python3.10/site-packages/django/core/handlers/base.py", line 197, in _get_response
    response = wrapped_callback(request, *callback_args, **callback_kwargs)
  File "/usr/local/lib/python3.10/site-packages/django/views/generic/base.py", line 84, in view
    return self.dispatch(request, *args, **kwargs)
  File "/usr/local/lib/python3.10/site-packages/django/views/generic/base.py", line 119, in dispatch
    return handler(request, *args, **kwargs)
  File "/app/actualizador/views.py", line 121, in post
    task = recolectar_procesar.delay()  # Ejecuta la tarea de Celery
  File "/usr/local/lib/python3.10/site-packages/celery/app/task.py", line 444, in delay
    return self.apply_async(args, kwargs)
  File "/usr/local/lib/python3.10/site-packages/celery/app/task.py", line 594, in apply_async
    return app.send_task(
  File "/usr/local/lib/python3.10/site-packages/celery/app/base.py", line 801, in send_task
    amqp.send_task_message(P, name, message, **options)
  File "/usr/local/lib/python3.10/site-packages/celery/app/amqp.py", line 518, in send_task_message
    ret = producer.publish(
  File "/usr/local/lib/python3.10/site-packages/kombu/messaging.py", line 186, in publish
    return _publish(
  File "/usr/local/lib/python3.10/site-packages/kombu/connection.py", line 556, in _ensured
    return fun(*args, **kwargs)
  File "/usr/local/lib/python3.10/site-packages/kombu/messaging.py", line 195, in _publish
    channel = self.channel
  File "/usr/local/lib/python3.10/site-packages/kombu/messaging.py", line 218, in _get_channel
    channel = self._channel = channel()
  File "/usr/local/lib/python3.10/site-packages/kombu/utils/functional.py", line 34, in __call__
    value = self.__value__ = self.__contract__()
  File "/usr/local/lib/python3.10/site-packages/kombu/messaging.py", line 234, in <lambda>
    channel = ChannelPromise(lambda: connection.default_channel)
  File "/usr/local/lib/python3.10/site-packages/kombu/connection.py", line 953, in default_channel
    self._ensure_connection(**conn_opts)
  File "/usr/local/lib/python3.10/site-packages/kombu/connection.py", line 458, in _ensure_connection
    with ctx():
  File "/usr/local/lib/python3.10/contextlib.py", line 153, in __exit__
    self.gen.throw(typ, value, traceback)
  File "/usr/local/lib/python3.10/site-packages/kombu/connection.py", line 476, in _reraise_as_library_errors
    raise ConnectionError(str(exc)) from exc
kombu.exceptions.OperationalError: [Errno 111] Connection refused
2024-10-02 16:54:36,534 - WARNING - Not Found: /favicon.ico
2024-10-02 16:58:48,480 - INFO - file_cache is only supported with oauth2client<4.0.0
2024-10-02 16:58:48,488 - INFO - file_cache is only supported with oauth2client<4.0.0
2024-10-02 16:58:48,495 - INFO - file_cache is only supported with oauth2client<4.0.0
2024-10-02 16:58:54,573 - INFO - file_cache is only supported with oauth2client<4.0.0
2024-10-02 16:58:54,579 - INFO - file_cache is only supported with oauth2client<4.0.0
2024-10-02 16:58:54,585 - INFO - file_cache is only supported with oauth2client<4.0.0
2024-10-02 16:59:00,869 - ERROR - Internal Server Error: /actualizar/
Traceback (most recent call last):
  File "/usr/local/lib/python3.10/site-packages/kombu/utils/functional.py", line 32, in __call__
    return self.__value__
AttributeError: 'ChannelPromise' object has no attribute '__value__'

During handling of the above exception, another exception occurred:

Traceback (most recent call last):
  File "/usr/local/lib/python3.10/site-packages/kombu/connection.py", line 472, in _reraise_as_library_errors
    yield
  File "/usr/local/lib/python3.10/site-packages/kombu/connection.py", line 459, in _ensure_connection
    return retry_over_time(
  File "/usr/local/lib/python3.10/site-packages/kombu/utils/functional.py", line 318, in retry_over_time
    return fun(*args, **kwargs)
  File "/usr/local/lib/python3.10/site-packages/kombu/connection.py", line 934, in _connection_factory
    self._connection = self._establish_connection()
  File "/usr/local/lib/python3.10/site-packages/kombu/connection.py", line 860, in _establish_connection
    conn = self.transport.establish_connection()
  File "/usr/local/lib/python3.10/site-packages/kombu/transport/pyamqp.py", line 203, in establish_connection
    conn.connect()
  File "/usr/local/lib/python3.10/site-packages/amqp/connection.py", line 324, in connect
    self.transport.connect()
  File "/usr/local/lib/python3.10/site-packages/amqp/transport.py", line 129, in connect
    self._connect(self.host, self.port, self.connect_timeout)
  File "/usr/local/lib/python3.10/site-packages/amqp/transport.py", line 184, in _connect
    self.sock.connect(sa)
ConnectionRefusedError: [Errno 111] Connection refused

The above exception was the direct cause of the following exception:

Traceback (most recent call last):
  File "/usr/local/lib/python3.10/site-packages/django/core/handlers/exception.py", line 55, in inner
    response = get_response(request)
  File "/usr/local/lib/python3.10/site-packages/django/core/handlers/base.py", line 197, in _get_response
    response = wrapped_callback(request, *callback_args, **callback_kwargs)
  File "/usr/local/lib/python3.10/site-packages/django/views/generic/base.py", line 84, in view
    return self.dispatch(request, *args, **kwargs)
  File "/usr/local/lib/python3.10/site-packages/django/views/generic/base.py", line 119, in dispatch
    return handler(request, *args, **kwargs)
  File "/app/actualizador/views.py", line 121, in post
    task = recolectar_procesar.delay()  # Ejecuta la tarea de Celery
  File "/usr/local/lib/python3.10/site-packages/celery/app/task.py", line 444, in delay
    return self.apply_async(args, kwargs)
  File "/usr/local/lib/python3.10/site-packages/celery/app/task.py", line 594, in apply_async
    return app.send_task(
  File "/usr/local/lib/python3.10/site-packages/celery/app/base.py", line 801, in send_task
    amqp.send_task_message(P, name, message, **options)
  File "/usr/local/lib/python3.10/site-packages/celery/app/amqp.py", line 518, in send_task_message
    ret = producer.publish(
  File "/usr/local/lib/python3.10/site-packages/kombu/messaging.py", line 186, in publish
    return _publish(
  File "/usr/local/lib/python3.10/site-packages/kombu/connection.py", line 556, in _ensured
    return fun(*args, **kwargs)
  File "/usr/local/lib/python3.10/site-packages/kombu/messaging.py", line 195, in _publish
    channel = self.channel
  File "/usr/local/lib/python3.10/site-packages/kombu/messaging.py", line 218, in _get_channel
    channel = self._channel = channel()
  File "/usr/local/lib/python3.10/site-packages/kombu/utils/functional.py", line 34, in __call__
    value = self.__value__ = self.__contract__()
  File "/usr/local/lib/python3.10/site-packages/kombu/messaging.py", line 234, in <lambda>
    channel = ChannelPromise(lambda: connection.default_channel)
  File "/usr/local/lib/python3.10/site-packages/kombu/connection.py", line 953, in default_channel
    self._ensure_connection(**conn_opts)
  File "/usr/local/lib/python3.10/site-packages/kombu/connection.py", line 458, in _ensure_connection
    with ctx():
  File "/usr/local/lib/python3.10/contextlib.py", line 153, in __exit__
    self.gen.throw(typ, value, traceback)
  File "/usr/local/lib/python3.10/site-packages/kombu/connection.py", line 476, in _reraise_as_library_errors
    raise ConnectionError(str(exc)) from exc
kombu.exceptions.OperationalError: [Errno 111] Connection refused
2024-10-02 16:59:01,207 - WARNING - Not Found: /favicon.ico
2024-10-02 17:00:04,307 - INFO - file_cache is only supported with oauth2client<4.0.0
2024-10-02 17:00:04,317 - INFO - file_cache is only supported with oauth2client<4.0.0
2024-10-02 17:00:04,323 - INFO - file_cache is only supported with oauth2client<4.0.0
2024-10-02 17:00:16,892 - INFO - file_cache is only supported with oauth2client<4.0.0
2024-10-02 17:00:16,899 - INFO - file_cache is only supported with oauth2client<4.0.0
2024-10-02 17:00:16,905 - INFO - file_cache is only supported with oauth2client<4.0.0
2024-10-02 17:00:23,187 - ERROR - Internal Server Error: /actualizar/
Traceback (most recent call last):
  File "/usr/local/lib/python3.10/site-packages/kombu/utils/functional.py", line 32, in __call__
    return self.__value__
AttributeError: 'ChannelPromise' object has no attribute '__value__'

During handling of the above exception, another exception occurred:

Traceback (most recent call last):
  File "/usr/local/lib/python3.10/site-packages/kombu/connection.py", line 472, in _reraise_as_library_errors
    yield
  File "/usr/local/lib/python3.10/site-packages/kombu/connection.py", line 459, in _ensure_connection
    return retry_over_time(
  File "/usr/local/lib/python3.10/site-packages/kombu/utils/functional.py", line 318, in retry_over_time
    return fun(*args, **kwargs)
  File "/usr/local/lib/python3.10/site-packages/kombu/connection.py", line 934, in _connection_factory
    self._connection = self._establish_connection()
  File "/usr/local/lib/python3.10/site-packages/kombu/connection.py", line 860, in _establish_connection
    conn = self.transport.establish_connection()
  File "/usr/local/lib/python3.10/site-packages/kombu/transport/pyamqp.py", line 203, in establish_connection
    conn.connect()
  File "/usr/local/lib/python3.10/site-packages/amqp/connection.py", line 324, in connect
    self.transport.connect()
  File "/usr/local/lib/python3.10/site-packages/amqp/transport.py", line 129, in connect
    self._connect(self.host, self.port, self.connect_timeout)
  File "/usr/local/lib/python3.10/site-packages/amqp/transport.py", line 184, in _connect
    self.sock.connect(sa)
ConnectionRefusedError: [Errno 111] Connection refused

The above exception was the direct cause of the following exception:

Traceback (most recent call last):
  File "/usr/local/lib/python3.10/site-packages/django/core/handlers/exception.py", line 55, in inner
    response = get_response(request)
  File "/usr/local/lib/python3.10/site-packages/django/core/handlers/base.py", line 197, in _get_response
    response = wrapped_callback(request, *callback_args, **callback_kwargs)
  File "/usr/local/lib/python3.10/site-packages/django/views/generic/base.py", line 84, in view
    return self.dispatch(request, *args, **kwargs)
  File "/usr/local/lib/python3.10/site-packages/django/views/generic/base.py", line 119, in dispatch
    return handler(request, *args, **kwargs)
  File "/app/actualizador/views.py", line 121, in post
    task = recolectar_procesar.delay()  # Ejecuta la tarea de Celery
  File "/usr/local/lib/python3.10/site-packages/celery/app/task.py", line 444, in delay
    return self.apply_async(args, kwargs)
  File "/usr/local/lib/python3.10/site-packages/celery/app/task.py", line 594, in apply_async
    return app.send_task(
  File "/usr/local/lib/python3.10/site-packages/celery/app/base.py", line 801, in send_task
    amqp.send_task_message(P, name, message, **options)
  File "/usr/local/lib/python3.10/site-packages/celery/app/amqp.py", line 518, in send_task_message
    ret = producer.publish(
  File "/usr/local/lib/python3.10/site-packages/kombu/messaging.py", line 186, in publish
    return _publish(
  File "/usr/local/lib/python3.10/site-packages/kombu/connection.py", line 556, in _ensured
    return fun(*args, **kwargs)
  File "/usr/local/lib/python3.10/site-packages/kombu/messaging.py", line 195, in _publish
    channel = self.channel
  File "/usr/local/lib/python3.10/site-packages/kombu/messaging.py", line 218, in _get_channel
    channel = self._channel = channel()
  File "/usr/local/lib/python3.10/site-packages/kombu/utils/functional.py", line 34, in __call__
    value = self.__value__ = self.__contract__()
  File "/usr/local/lib/python3.10/site-packages/kombu/messaging.py", line 234, in <lambda>
    channel = ChannelPromise(lambda: connection.default_channel)
  File "/usr/local/lib/python3.10/site-packages/kombu/connection.py", line 953, in default_channel
    self._ensure_connection(**conn_opts)
  File "/usr/local/lib/python3.10/site-packages/kombu/connection.py", line 458, in _ensure_connection
    with ctx():
  File "/usr/local/lib/python3.10/contextlib.py", line 153, in __exit__
    self.gen.throw(typ, value, traceback)
  File "/usr/local/lib/python3.10/site-packages/kombu/connection.py", line 476, in _reraise_as_library_errors
    raise ConnectionError(str(exc)) from exc
kombu.exceptions.OperationalError: [Errno 111] Connection refused
2024-10-02 17:04:19,257 - INFO - file_cache is only supported with oauth2client<4.0.0
2024-10-02 17:04:19,263 - INFO - file_cache is only supported with oauth2client<4.0.0
2024-10-02 17:04:19,271 - INFO - file_cache is only supported with oauth2client<4.0.0
2024-10-02 17:04:22,760 - INFO - file_cache is only supported with oauth2client<4.0.0
2024-10-02 17:04:22,767 - INFO - file_cache is only supported with oauth2client<4.0.0
2024-10-02 17:04:22,772 - INFO - file_cache is only supported with oauth2client<4.0.0
2024-10-02 17:04:29,032 - ERROR - Internal Server Error: /actualizar/
Traceback (most recent call last):
  File "/usr/local/lib/python3.10/site-packages/kombu/utils/functional.py", line 32, in __call__
    return self.__value__
AttributeError: 'ChannelPromise' object has no attribute '__value__'

During handling of the above exception, another exception occurred:

Traceback (most recent call last):
  File "/usr/local/lib/python3.10/site-packages/kombu/connection.py", line 472, in _reraise_as_library_errors
    yield
  File "/usr/local/lib/python3.10/site-packages/kombu/connection.py", line 459, in _ensure_connection
    return retry_over_time(
  File "/usr/local/lib/python3.10/site-packages/kombu/utils/functional.py", line 318, in retry_over_time
    return fun(*args, **kwargs)
  File "/usr/local/lib/python3.10/site-packages/kombu/connection.py", line 934, in _connection_factory
    self._connection = self._establish_connection()
  File "/usr/local/lib/python3.10/site-packages/kombu/connection.py", line 860, in _establish_connection
    conn = self.transport.establish_connection()
  File "/usr/local/lib/python3.10/site-packages/kombu/transport/pyamqp.py", line 203, in establish_connection
    conn.connect()
  File "/usr/local/lib/python3.10/site-packages/amqp/connection.py", line 324, in connect
    self.transport.connect()
  File "/usr/local/lib/python3.10/site-packages/amqp/transport.py", line 129, in connect
    self._connect(self.host, self.port, self.connect_timeout)
  File "/usr/local/lib/python3.10/site-packages/amqp/transport.py", line 184, in _connect
    self.sock.connect(sa)
ConnectionRefusedError: [Errno 111] Connection refused

The above exception was the direct cause of the following exception:

Traceback (most recent call last):
  File "/usr/local/lib/python3.10/site-packages/django/core/handlers/exception.py", line 55, in inner
    response = get_response(request)
  File "/usr/local/lib/python3.10/site-packages/django/core/handlers/base.py", line 197, in _get_response
    response = wrapped_callback(request, *callback_args, **callback_kwargs)
  File "/usr/local/lib/python3.10/site-packages/django/views/generic/base.py", line 84, in view
    return self.dispatch(request, *args, **kwargs)
  File "/usr/local/lib/python3.10/site-packages/django/views/generic/base.py", line 119, in dispatch
    return handler(request, *args, **kwargs)
  File "/app/actualizador/views.py", line 121, in post
    task = recolectar_procesar.delay()  # Ejecuta la tarea de Celery
  File "/usr/local/lib/python3.10/site-packages/celery/app/task.py", line 444, in delay
    return self.apply_async(args, kwargs)
  File "/usr/local/lib/python3.10/site-packages/celery/app/task.py", line 594, in apply_async
    return app.send_task(
  File "/usr/local/lib/python3.10/site-packages/celery/app/base.py", line 801, in send_task
    amqp.send_task_message(P, name, message, **options)
  File "/usr/local/lib/python3.10/site-packages/celery/app/amqp.py", line 518, in send_task_message
    ret = producer.publish(
  File "/usr/local/lib/python3.10/site-packages/kombu/messaging.py", line 186, in publish
    return _publish(
  File "/usr/local/lib/python3.10/site-packages/kombu/connection.py", line 556, in _ensured
    return fun(*args, **kwargs)
  File "/usr/local/lib/python3.10/site-packages/kombu/messaging.py", line 195, in _publish
    channel = self.channel
  File "/usr/local/lib/python3.10/site-packages/kombu/messaging.py", line 218, in _get_channel
    channel = self._channel = channel()
  File "/usr/local/lib/python3.10/site-packages/kombu/utils/functional.py", line 34, in __call__
    value = self.__value__ = self.__contract__()
  File "/usr/local/lib/python3.10/site-packages/kombu/messaging.py", line 234, in <lambda>
    channel = ChannelPromise(lambda: connection.default_channel)
  File "/usr/local/lib/python3.10/site-packages/kombu/connection.py", line 953, in default_channel
    self._ensure_connection(**conn_opts)
  File "/usr/local/lib/python3.10/site-packages/kombu/connection.py", line 458, in _ensure_connection
    with ctx():
  File "/usr/local/lib/python3.10/contextlib.py", line 153, in __exit__
    self.gen.throw(typ, value, traceback)
  File "/usr/local/lib/python3.10/site-packages/kombu/connection.py", line 476, in _reraise_as_library_errors
    raise ConnectionError(str(exc)) from exc
kombu.exceptions.OperationalError: [Errno 111] Connection refused
2024-10-02 17:06:50,402 - INFO - file_cache is only supported with oauth2client<4.0.0
2024-10-02 17:06:50,408 - INFO - file_cache is only supported with oauth2client<4.0.0
2024-10-02 17:06:50,415 - INFO - file_cache is only supported with oauth2client<4.0.0
2024-10-02 17:06:53,416 - INFO - file_cache is only supported with oauth2client<4.0.0
2024-10-02 17:06:53,421 - INFO - file_cache is only supported with oauth2client<4.0.0
2024-10-02 17:06:53,429 - INFO - file_cache is only supported with oauth2client<4.0.0
2024-10-02 17:06:59,691 - ERROR - Internal Server Error: /actualizar/
Traceback (most recent call last):
  File "/usr/local/lib/python3.10/site-packages/kombu/utils/functional.py", line 32, in __call__
    return self.__value__
AttributeError: 'ChannelPromise' object has no attribute '__value__'

During handling of the above exception, another exception occurred:

Traceback (most recent call last):
  File "/usr/local/lib/python3.10/site-packages/kombu/connection.py", line 472, in _reraise_as_library_errors
    yield
  File "/usr/local/lib/python3.10/site-packages/kombu/connection.py", line 459, in _ensure_connection
    return retry_over_time(
  File "/usr/local/lib/python3.10/site-packages/kombu/utils/functional.py", line 318, in retry_over_time
    return fun(*args, **kwargs)
  File "/usr/local/lib/python3.10/site-packages/kombu/connection.py", line 934, in _connection_factory
    self._connection = self._establish_connection()
  File "/usr/local/lib/python3.10/site-packages/kombu/connection.py", line 860, in _establish_connection
    conn = self.transport.establish_connection()
  File "/usr/local/lib/python3.10/site-packages/kombu/transport/pyamqp.py", line 203, in establish_connection
    conn.connect()
  File "/usr/local/lib/python3.10/site-packages/amqp/connection.py", line 324, in connect
    self.transport.connect()
  File "/usr/local/lib/python3.10/site-packages/amqp/transport.py", line 129, in connect
    self._connect(self.host, self.port, self.connect_timeout)
  File "/usr/local/lib/python3.10/site-packages/amqp/transport.py", line 184, in _connect
    self.sock.connect(sa)
ConnectionRefusedError: [Errno 111] Connection refused

The above exception was the direct cause of the following exception:

Traceback (most recent call last):
  File "/usr/local/lib/python3.10/site-packages/django/core/handlers/exception.py", line 55, in inner
    response = get_response(request)
  File "/usr/local/lib/python3.10/site-packages/django/core/handlers/base.py", line 197, in _get_response
    response = wrapped_callback(request, *callback_args, **callback_kwargs)
  File "/usr/local/lib/python3.10/site-packages/django/views/generic/base.py", line 84, in view
    return self.dispatch(request, *args, **kwargs)
  File "/usr/local/lib/python3.10/site-packages/django/views/generic/base.py", line 119, in dispatch
    return handler(request, *args, **kwargs)
  File "/app/actualizador/views.py", line 121, in post
    task = recolectar_procesar.delay()  # Ejecuta la tarea de Celery
  File "/usr/local/lib/python3.10/site-packages/celery/app/task.py", line 444, in delay
    return self.apply_async(args, kwargs)
  File "/usr/local/lib/python3.10/site-packages/celery/app/task.py", line 594, in apply_async
    return app.send_task(
  File "/usr/local/lib/python3.10/site-packages/celery/app/base.py", line 801, in send_task
    amqp.send_task_message(P, name, message, **options)
  File "/usr/local/lib/python3.10/site-packages/celery/app/amqp.py", line 518, in send_task_message
    ret = producer.publish(
  File "/usr/local/lib/python3.10/site-packages/kombu/messaging.py", line 186, in publish
    return _publish(
  File "/usr/local/lib/python3.10/site-packages/kombu/connection.py", line 556, in _ensured
    return fun(*args, **kwargs)
  File "/usr/local/lib/python3.10/site-packages/kombu/messaging.py", line 195, in _publish
    channel = self.channel
  File "/usr/local/lib/python3.10/site-packages/kombu/messaging.py", line 218, in _get_channel
    channel = self._channel = channel()
  File "/usr/local/lib/python3.10/site-packages/kombu/utils/functional.py", line 34, in __call__
    value = self.__value__ = self.__contract__()
  File "/usr/local/lib/python3.10/site-packages/kombu/messaging.py", line 234, in <lambda>
    channel = ChannelPromise(lambda: connection.default_channel)
  File "/usr/local/lib/python3.10/site-packages/kombu/connection.py", line 953, in default_channel
    self._ensure_connection(**conn_opts)
  File "/usr/local/lib/python3.10/site-packages/kombu/connection.py", line 458, in _ensure_connection
    with ctx():
  File "/usr/local/lib/python3.10/contextlib.py", line 153, in __exit__
    self.gen.throw(typ, value, traceback)
  File "/usr/local/lib/python3.10/site-packages/kombu/connection.py", line 476, in _reraise_as_library_errors
    raise ConnectionError(str(exc)) from exc
kombu.exceptions.OperationalError: [Errno 111] Connection refused
2024-10-02 17:09:13,261 - INFO - file_cache is only supported with oauth2client<4.0.0
2024-10-02 17:09:13,269 - INFO - file_cache is only supported with oauth2client<4.0.0
2024-10-02 17:09:13,275 - INFO - file_cache is only supported with oauth2client<4.0.0
2024-10-02 17:09:28,658 - INFO - file_cache is only supported with oauth2client<4.0.0
2024-10-02 17:09:28,664 - INFO - file_cache is only supported with oauth2client<4.0.0
2024-10-02 17:09:28,672 - INFO - file_cache is only supported with oauth2client<4.0.0
2024-10-02 17:09:28,849 - WARNING - No hostname was supplied. Reverting to default 'localhost'
2024-10-02 17:09:35,025 - ERROR - Internal Server Error: /actualizar/
Traceback (most recent call last):
  File "/usr/local/lib/python3.10/site-packages/kombu/utils/functional.py", line 32, in __call__
    return self.__value__
AttributeError: 'ChannelPromise' object has no attribute '__value__'

During handling of the above exception, another exception occurred:

Traceback (most recent call last):
  File "/usr/local/lib/python3.10/site-packages/kombu/connection.py", line 472, in _reraise_as_library_errors
    yield
  File "/usr/local/lib/python3.10/site-packages/kombu/connection.py", line 459, in _ensure_connection
    return retry_over_time(
  File "/usr/local/lib/python3.10/site-packages/kombu/utils/functional.py", line 318, in retry_over_time
    return fun(*args, **kwargs)
  File "/usr/local/lib/python3.10/site-packages/kombu/connection.py", line 934, in _connection_factory
    self._connection = self._establish_connection()
  File "/usr/local/lib/python3.10/site-packages/kombu/connection.py", line 860, in _establish_connection
    conn = self.transport.establish_connection()
  File "/usr/local/lib/python3.10/site-packages/kombu/transport/pyamqp.py", line 203, in establish_connection
    conn.connect()
  File "/usr/local/lib/python3.10/site-packages/amqp/connection.py", line 324, in connect
    self.transport.connect()
  File "/usr/local/lib/python3.10/site-packages/amqp/transport.py", line 129, in connect
    self._connect(self.host, self.port, self.connect_timeout)
  File "/usr/local/lib/python3.10/site-packages/amqp/transport.py", line 184, in _connect
    self.sock.connect(sa)
ConnectionRefusedError: [Errno 111] Connection refused

The above exception was the direct cause of the following exception:

Traceback (most recent call last):
  File "/usr/local/lib/python3.10/site-packages/django/core/handlers/exception.py", line 55, in inner
    response = get_response(request)
  File "/usr/local/lib/python3.10/site-packages/django/core/handlers/base.py", line 197, in _get_response
    response = wrapped_callback(request, *callback_args, **callback_kwargs)
  File "/usr/local/lib/python3.10/site-packages/django/views/generic/base.py", line 84, in view
    return self.dispatch(request, *args, **kwargs)
  File "/usr/local/lib/python3.10/site-packages/django/views/generic/base.py", line 119, in dispatch
    return handler(request, *args, **kwargs)
  File "/app/actualizador/views.py", line 121, in post
    task = recolectar_procesar.delay()  # Ejecuta la tarea de Celery
  File "/usr/local/lib/python3.10/site-packages/celery/app/task.py", line 444, in delay
    return self.apply_async(args, kwargs)
  File "/usr/local/lib/python3.10/site-packages/celery/app/task.py", line 594, in apply_async
    return app.send_task(
  File "/usr/local/lib/python3.10/site-packages/celery/app/base.py", line 801, in send_task
    amqp.send_task_message(P, name, message, **options)
  File "/usr/local/lib/python3.10/site-packages/celery/app/amqp.py", line 518, in send_task_message
    ret = producer.publish(
  File "/usr/local/lib/python3.10/site-packages/kombu/messaging.py", line 186, in publish
    return _publish(
  File "/usr/local/lib/python3.10/site-packages/kombu/connection.py", line 556, in _ensured
    return fun(*args, **kwargs)
  File "/usr/local/lib/python3.10/site-packages/kombu/messaging.py", line 195, in _publish
    channel = self.channel
  File "/usr/local/lib/python3.10/site-packages/kombu/messaging.py", line 218, in _get_channel
    channel = self._channel = channel()
  File "/usr/local/lib/python3.10/site-packages/kombu/utils/functional.py", line 34, in __call__
    value = self.__value__ = self.__contract__()
  File "/usr/local/lib/python3.10/site-packages/kombu/messaging.py", line 234, in <lambda>
    channel = ChannelPromise(lambda: connection.default_channel)
  File "/usr/local/lib/python3.10/site-packages/kombu/connection.py", line 953, in default_channel
    self._ensure_connection(**conn_opts)
  File "/usr/local/lib/python3.10/site-packages/kombu/connection.py", line 458, in _ensure_connection
    with ctx():
  File "/usr/local/lib/python3.10/contextlib.py", line 153, in __exit__
    self.gen.throw(typ, value, traceback)
  File "/usr/local/lib/python3.10/site-packages/kombu/connection.py", line 476, in _reraise_as_library_errors
    raise ConnectionError(str(exc)) from exc
kombu.exceptions.OperationalError: [Errno 111] Connection refused
2024-10-02 17:10:54,280 - INFO - file_cache is only supported with oauth2client<4.0.0
2024-10-02 17:10:54,288 - INFO - file_cache is only supported with oauth2client<4.0.0
2024-10-02 17:10:54,295 - INFO - file_cache is only supported with oauth2client<4.0.0
2024-10-02 17:10:58,168 - INFO - file_cache is only supported with oauth2client<4.0.0
2024-10-02 17:10:58,174 - INFO - file_cache is only supported with oauth2client<4.0.0
2024-10-02 17:10:58,180 - INFO - file_cache is only supported with oauth2client<4.0.0
2024-10-02 17:10:58,335 - WARNING - No hostname was supplied. Reverting to default 'localhost'
2024-10-02 17:11:04,511 - ERROR - Internal Server Error: /actualizar/
Traceback (most recent call last):
  File "/usr/local/lib/python3.10/site-packages/kombu/utils/functional.py", line 32, in __call__
    return self.__value__
AttributeError: 'ChannelPromise' object has no attribute '__value__'

During handling of the above exception, another exception occurred:

Traceback (most recent call last):
  File "/usr/local/lib/python3.10/site-packages/kombu/connection.py", line 472, in _reraise_as_library_errors
    yield
  File "/usr/local/lib/python3.10/site-packages/kombu/connection.py", line 459, in _ensure_connection
    return retry_over_time(
  File "/usr/local/lib/python3.10/site-packages/kombu/utils/functional.py", line 318, in retry_over_time
    return fun(*args, **kwargs)
  File "/usr/local/lib/python3.10/site-packages/kombu/connection.py", line 934, in _connection_factory
    self._connection = self._establish_connection()
  File "/usr/local/lib/python3.10/site-packages/kombu/connection.py", line 860, in _establish_connection
    conn = self.transport.establish_connection()
  File "/usr/local/lib/python3.10/site-packages/kombu/transport/pyamqp.py", line 203, in establish_connection
    conn.connect()
  File "/usr/local/lib/python3.10/site-packages/amqp/connection.py", line 324, in connect
    self.transport.connect()
  File "/usr/local/lib/python3.10/site-packages/amqp/transport.py", line 129, in connect
    self._connect(self.host, self.port, self.connect_timeout)
  File "/usr/local/lib/python3.10/site-packages/amqp/transport.py", line 184, in _connect
    self.sock.connect(sa)
ConnectionRefusedError: [Errno 111] Connection refused

The above exception was the direct cause of the following exception:

Traceback (most recent call last):
  File "/usr/local/lib/python3.10/site-packages/django/core/handlers/exception.py", line 55, in inner
    response = get_response(request)
  File "/usr/local/lib/python3.10/site-packages/django/core/handlers/base.py", line 197, in _get_response
    response = wrapped_callback(request, *callback_args, **callback_kwargs)
  File "/usr/local/lib/python3.10/site-packages/django/views/generic/base.py", line 84, in view
    return self.dispatch(request, *args, **kwargs)
  File "/usr/local/lib/python3.10/site-packages/django/views/generic/base.py", line 119, in dispatch
    return handler(request, *args, **kwargs)
  File "/app/actualizador/views.py", line 121, in post
    task = recolectar_procesar.delay()  # Ejecuta la tarea de Celery
  File "/usr/local/lib/python3.10/site-packages/celery/app/task.py", line 444, in delay
    return self.apply_async(args, kwargs)
  File "/usr/local/lib/python3.10/site-packages/celery/app/task.py", line 594, in apply_async
    return app.send_task(
  File "/usr/local/lib/python3.10/site-packages/celery/app/base.py", line 801, in send_task
    amqp.send_task_message(P, name, message, **options)
  File "/usr/local/lib/python3.10/site-packages/celery/app/amqp.py", line 518, in send_task_message
    ret = producer.publish(
  File "/usr/local/lib/python3.10/site-packages/kombu/messaging.py", line 186, in publish
    return _publish(
  File "/usr/local/lib/python3.10/site-packages/kombu/connection.py", line 556, in _ensured
    return fun(*args, **kwargs)
  File "/usr/local/lib/python3.10/site-packages/kombu/messaging.py", line 195, in _publish
    channel = self.channel
  File "/usr/local/lib/python3.10/site-packages/kombu/messaging.py", line 218, in _get_channel
    channel = self._channel = channel()
  File "/usr/local/lib/python3.10/site-packages/kombu/utils/functional.py", line 34, in __call__
    value = self.__value__ = self.__contract__()
  File "/usr/local/lib/python3.10/site-packages/kombu/messaging.py", line 234, in <lambda>
    channel = ChannelPromise(lambda: connection.default_channel)
  File "/usr/local/lib/python3.10/site-packages/kombu/connection.py", line 953, in default_channel
    self._ensure_connection(**conn_opts)
  File "/usr/local/lib/python3.10/site-packages/kombu/connection.py", line 458, in _ensure_connection
    with ctx():
  File "/usr/local/lib/python3.10/contextlib.py", line 153, in __exit__
    self.gen.throw(typ, value, traceback)
  File "/usr/local/lib/python3.10/site-packages/kombu/connection.py", line 476, in _reraise_as_library_errors
    raise ConnectionError(str(exc)) from exc
kombu.exceptions.OperationalError: [Errno 111] Connection refused
2024-10-02 17:13:44,175 - INFO - file_cache is only supported with oauth2client<4.0.0
2024-10-02 17:13:44,181 - INFO - file_cache is only supported with oauth2client<4.0.0
2024-10-02 17:13:44,190 - INFO - file_cache is only supported with oauth2client<4.0.0
2024-10-02 17:13:47,026 - INFO - file_cache is only supported with oauth2client<4.0.0
2024-10-02 17:13:47,034 - INFO - file_cache is only supported with oauth2client<4.0.0
2024-10-02 17:13:47,041 - INFO - file_cache is only supported with oauth2client<4.0.0
2024-10-02 17:13:53,408 - ERROR - Internal Server Error: /actualizar/
Traceback (most recent call last):
  File "/usr/local/lib/python3.10/site-packages/kombu/utils/functional.py", line 32, in __call__
    return self.__value__
AttributeError: 'ChannelPromise' object has no attribute '__value__'

During handling of the above exception, another exception occurred:

Traceback (most recent call last):
  File "/usr/local/lib/python3.10/site-packages/kombu/connection.py", line 472, in _reraise_as_library_errors
    yield
  File "/usr/local/lib/python3.10/site-packages/kombu/connection.py", line 459, in _ensure_connection
    return retry_over_time(
  File "/usr/local/lib/python3.10/site-packages/kombu/utils/functional.py", line 318, in retry_over_time
    return fun(*args, **kwargs)
  File "/usr/local/lib/python3.10/site-packages/kombu/connection.py", line 934, in _connection_factory
    self._connection = self._establish_connection()
  File "/usr/local/lib/python3.10/site-packages/kombu/connection.py", line 860, in _establish_connection
    conn = self.transport.establish_connection()
  File "/usr/local/lib/python3.10/site-packages/kombu/transport/pyamqp.py", line 203, in establish_connection
    conn.connect()
  File "/usr/local/lib/python3.10/site-packages/amqp/connection.py", line 324, in connect
    self.transport.connect()
  File "/usr/local/lib/python3.10/site-packages/amqp/transport.py", line 129, in connect
    self._connect(self.host, self.port, self.connect_timeout)
  File "/usr/local/lib/python3.10/site-packages/amqp/transport.py", line 184, in _connect
    self.sock.connect(sa)
ConnectionRefusedError: [Errno 111] Connection refused

The above exception was the direct cause of the following exception:

Traceback (most recent call last):
  File "/usr/local/lib/python3.10/site-packages/django/core/handlers/exception.py", line 55, in inner
    response = get_response(request)
  File "/usr/local/lib/python3.10/site-packages/django/core/handlers/base.py", line 197, in _get_response
    response = wrapped_callback(request, *callback_args, **callback_kwargs)
  File "/usr/local/lib/python3.10/site-packages/django/views/generic/base.py", line 84, in view
    return self.dispatch(request, *args, **kwargs)
  File "/usr/local/lib/python3.10/site-packages/django/views/generic/base.py", line 119, in dispatch
    return handler(request, *args, **kwargs)
  File "/app/actualizador/views.py", line 121, in post
    task = recolectar_procesar.delay()  # Ejecuta la tarea de Celery
  File "/usr/local/lib/python3.10/site-packages/celery/app/task.py", line 444, in delay
    return self.apply_async(args, kwargs)
  File "/usr/local/lib/python3.10/site-packages/celery/app/task.py", line 594, in apply_async
    return app.send_task(
  File "/usr/local/lib/python3.10/site-packages/celery/app/base.py", line 801, in send_task
    amqp.send_task_message(P, name, message, **options)
  File "/usr/local/lib/python3.10/site-packages/celery/app/amqp.py", line 518, in send_task_message
    ret = producer.publish(
  File "/usr/local/lib/python3.10/site-packages/kombu/messaging.py", line 186, in publish
    return _publish(
  File "/usr/local/lib/python3.10/site-packages/kombu/connection.py", line 556, in _ensured
    return fun(*args, **kwargs)
  File "/usr/local/lib/python3.10/site-packages/kombu/messaging.py", line 195, in _publish
    channel = self.channel
  File "/usr/local/lib/python3.10/site-packages/kombu/messaging.py", line 218, in _get_channel
    channel = self._channel = channel()
  File "/usr/local/lib/python3.10/site-packages/kombu/utils/functional.py", line 34, in __call__
    value = self.__value__ = self.__contract__()
  File "/usr/local/lib/python3.10/site-packages/kombu/messaging.py", line 234, in <lambda>
    channel = ChannelPromise(lambda: connection.default_channel)
  File "/usr/local/lib/python3.10/site-packages/kombu/connection.py", line 953, in default_channel
    self._ensure_connection(**conn_opts)
  File "/usr/local/lib/python3.10/site-packages/kombu/connection.py", line 458, in _ensure_connection
    with ctx():
  File "/usr/local/lib/python3.10/contextlib.py", line 153, in __exit__
    self.gen.throw(typ, value, traceback)
  File "/usr/local/lib/python3.10/site-packages/kombu/connection.py", line 476, in _reraise_as_library_errors
    raise ConnectionError(str(exc)) from exc
kombu.exceptions.OperationalError: [Errno 111] Connection refused
2024-10-02 17:43:35,298 - INFO - file_cache is only supported with oauth2client<4.0.0
2024-10-02 17:43:35,308 - INFO - file_cache is only supported with oauth2client<4.0.0
2024-10-02 17:43:35,314 - INFO - file_cache is only supported with oauth2client<4.0.0
2024-10-02 17:43:39,294 - INFO - file_cache is only supported with oauth2client<4.0.0
2024-10-02 17:43:39,298 - INFO - file_cache is only supported with oauth2client<4.0.0
2024-10-02 17:43:39,304 - INFO - file_cache is only supported with oauth2client<4.0.0
2024-10-02 17:43:39,448 - WARNING - No hostname was supplied. Reverting to default 'localhost'
2024-10-02 17:43:45,672 - ERROR - Internal Server Error: /actualizar/
Traceback (most recent call last):
  File "/usr/local/lib/python3.10/site-packages/kombu/utils/functional.py", line 32, in __call__
    return self.__value__
AttributeError: 'ChannelPromise' object has no attribute '__value__'

During handling of the above exception, another exception occurred:

Traceback (most recent call last):
  File "/usr/local/lib/python3.10/site-packages/kombu/connection.py", line 472, in _reraise_as_library_errors
    yield
  File "/usr/local/lib/python3.10/site-packages/kombu/connection.py", line 459, in _ensure_connection
    return retry_over_time(
  File "/usr/local/lib/python3.10/site-packages/kombu/utils/functional.py", line 318, in retry_over_time
    return fun(*args, **kwargs)
  File "/usr/local/lib/python3.10/site-packages/kombu/connection.py", line 934, in _connection_factory
    self._connection = self._establish_connection()
  File "/usr/local/lib/python3.10/site-packages/kombu/connection.py", line 860, in _establish_connection
    conn = self.transport.establish_connection()
  File "/usr/local/lib/python3.10/site-packages/kombu/transport/pyamqp.py", line 203, in establish_connection
    conn.connect()
  File "/usr/local/lib/python3.10/site-packages/amqp/connection.py", line 324, in connect
    self.transport.connect()
  File "/usr/local/lib/python3.10/site-packages/amqp/transport.py", line 129, in connect
    self._connect(self.host, self.port, self.connect_timeout)
  File "/usr/local/lib/python3.10/site-packages/amqp/transport.py", line 184, in _connect
    self.sock.connect(sa)
ConnectionRefusedError: [Errno 111] Connection refused

The above exception was the direct cause of the following exception:

Traceback (most recent call last):
  File "/usr/local/lib/python3.10/site-packages/django/core/handlers/exception.py", line 55, in inner
    response = get_response(request)
  File "/usr/local/lib/python3.10/site-packages/django/core/handlers/base.py", line 197, in _get_response
    response = wrapped_callback(request, *callback_args, **callback_kwargs)
  File "/usr/local/lib/python3.10/site-packages/django/views/generic/base.py", line 84, in view
    return self.dispatch(request, *args, **kwargs)
  File "/usr/local/lib/python3.10/site-packages/django/views/generic/base.py", line 119, in dispatch
    return handler(request, *args, **kwargs)
  File "/app/actualizador/views.py", line 121, in post
    task = recolectar_procesar.delay()  # Ejecuta la tarea de Celery
  File "/usr/local/lib/python3.10/site-packages/celery/app/task.py", line 444, in delay
    return self.apply_async(args, kwargs)
  File "/usr/local/lib/python3.10/site-packages/celery/app/task.py", line 594, in apply_async
    return app.send_task(
  File "/usr/local/lib/python3.10/site-packages/celery/app/base.py", line 801, in send_task
    amqp.send_task_message(P, name, message, **options)
  File "/usr/local/lib/python3.10/site-packages/celery/app/amqp.py", line 518, in send_task_message
    ret = producer.publish(
  File "/usr/local/lib/python3.10/site-packages/kombu/messaging.py", line 186, in publish
    return _publish(
  File "/usr/local/lib/python3.10/site-packages/kombu/connection.py", line 556, in _ensured
    return fun(*args, **kwargs)
  File "/usr/local/lib/python3.10/site-packages/kombu/messaging.py", line 195, in _publish
    channel = self.channel
  File "/usr/local/lib/python3.10/site-packages/kombu/messaging.py", line 218, in _get_channel
    channel = self._channel = channel()
  File "/usr/local/lib/python3.10/site-packages/kombu/utils/functional.py", line 34, in __call__
    value = self.__value__ = self.__contract__()
  File "/usr/local/lib/python3.10/site-packages/kombu/messaging.py", line 234, in <lambda>
    channel = ChannelPromise(lambda: connection.default_channel)
  File "/usr/local/lib/python3.10/site-packages/kombu/connection.py", line 953, in default_channel
    self._ensure_connection(**conn_opts)
  File "/usr/local/lib/python3.10/site-packages/kombu/connection.py", line 458, in _ensure_connection
    with ctx():
  File "/usr/local/lib/python3.10/contextlib.py", line 153, in __exit__
    self.gen.throw(typ, value, traceback)
  File "/usr/local/lib/python3.10/site-packages/kombu/connection.py", line 476, in _reraise_as_library_errors
    raise ConnectionError(str(exc)) from exc
kombu.exceptions.OperationalError: [Errno 111] Connection refused
2024-10-02 17:53:41,179 - INFO - file_cache is only supported with oauth2client<4.0.0
2024-10-02 17:53:41,185 - INFO - file_cache is only supported with oauth2client<4.0.0
2024-10-02 17:53:41,192 - INFO - file_cache is only supported with oauth2client<4.0.0
2024-10-02 17:53:47,334 - INFO - file_cache is only supported with oauth2client<4.0.0
2024-10-02 17:53:47,341 - INFO - file_cache is only supported with oauth2client<4.0.0
2024-10-02 17:53:47,350 - INFO - file_cache is only supported with oauth2client<4.0.0
2024-10-02 17:53:53,653 - ERROR - Internal Server Error: /actualizar/
Traceback (most recent call last):
  File "/usr/local/lib/python3.10/site-packages/kombu/utils/functional.py", line 32, in __call__
    return self.__value__
AttributeError: 'ChannelPromise' object has no attribute '__value__'

During handling of the above exception, another exception occurred:

Traceback (most recent call last):
  File "/usr/local/lib/python3.10/site-packages/kombu/connection.py", line 472, in _reraise_as_library_errors
    yield
  File "/usr/local/lib/python3.10/site-packages/kombu/connection.py", line 459, in _ensure_connection
    return retry_over_time(
  File "/usr/local/lib/python3.10/site-packages/kombu/utils/functional.py", line 318, in retry_over_time
    return fun(*args, **kwargs)
  File "/usr/local/lib/python3.10/site-packages/kombu/connection.py", line 934, in _connection_factory
    self._connection = self._establish_connection()
  File "/usr/local/lib/python3.10/site-packages/kombu/connection.py", line 860, in _establish_connection
    conn = self.transport.establish_connection()
  File "/usr/local/lib/python3.10/site-packages/kombu/transport/pyamqp.py", line 203, in establish_connection
    conn.connect()
  File "/usr/local/lib/python3.10/site-packages/amqp/connection.py", line 324, in connect
    self.transport.connect()
  File "/usr/local/lib/python3.10/site-packages/amqp/transport.py", line 129, in connect
    self._connect(self.host, self.port, self.connect_timeout)
  File "/usr/local/lib/python3.10/site-packages/amqp/transport.py", line 184, in _connect
    self.sock.connect(sa)
ConnectionRefusedError: [Errno 111] Connection refused

The above exception was the direct cause of the following exception:

Traceback (most recent call last):
  File "/usr/local/lib/python3.10/site-packages/django/core/handlers/exception.py", line 55, in inner
    response = get_response(request)
  File "/usr/local/lib/python3.10/site-packages/django/core/handlers/base.py", line 197, in _get_response
    response = wrapped_callback(request, *callback_args, **callback_kwargs)
  File "/usr/local/lib/python3.10/site-packages/django/views/generic/base.py", line 84, in view
    return self.dispatch(request, *args, **kwargs)
  File "/usr/local/lib/python3.10/site-packages/django/views/generic/base.py", line 119, in dispatch
    return handler(request, *args, **kwargs)
  File "/app/actualizador/views.py", line 127, in post
    task = actualizar.delay()
  File "/usr/local/lib/python3.10/site-packages/celery/app/task.py", line 444, in delay
    return self.apply_async(args, kwargs)
  File "/usr/local/lib/python3.10/site-packages/celery/app/task.py", line 594, in apply_async
    return app.send_task(
  File "/usr/local/lib/python3.10/site-packages/celery/app/base.py", line 801, in send_task
    amqp.send_task_message(P, name, message, **options)
  File "/usr/local/lib/python3.10/site-packages/celery/app/amqp.py", line 518, in send_task_message
    ret = producer.publish(
  File "/usr/local/lib/python3.10/site-packages/kombu/messaging.py", line 186, in publish
    return _publish(
  File "/usr/local/lib/python3.10/site-packages/kombu/connection.py", line 556, in _ensured
    return fun(*args, **kwargs)
  File "/usr/local/lib/python3.10/site-packages/kombu/messaging.py", line 195, in _publish
    channel = self.channel
  File "/usr/local/lib/python3.10/site-packages/kombu/messaging.py", line 218, in _get_channel
    channel = self._channel = channel()
  File "/usr/local/lib/python3.10/site-packages/kombu/utils/functional.py", line 34, in __call__
    value = self.__value__ = self.__contract__()
  File "/usr/local/lib/python3.10/site-packages/kombu/messaging.py", line 234, in <lambda>
    channel = ChannelPromise(lambda: connection.default_channel)
  File "/usr/local/lib/python3.10/site-packages/kombu/connection.py", line 953, in default_channel
    self._ensure_connection(**conn_opts)
  File "/usr/local/lib/python3.10/site-packages/kombu/connection.py", line 458, in _ensure_connection
    with ctx():
  File "/usr/local/lib/python3.10/contextlib.py", line 153, in __exit__
    self.gen.throw(typ, value, traceback)
  File "/usr/local/lib/python3.10/site-packages/kombu/connection.py", line 476, in _reraise_as_library_errors
    raise ConnectionError(str(exc)) from exc
kombu.exceptions.OperationalError: [Errno 111] Connection refused
2024-10-02 18:05:40,555 - INFO - file_cache is only supported with oauth2client<4.0.0
2024-10-02 18:05:40,562 - INFO - file_cache is only supported with oauth2client<4.0.0
2024-10-02 18:05:40,569 - INFO - file_cache is only supported with oauth2client<4.0.0
2024-10-02 18:05:44,187 - INFO - file_cache is only supported with oauth2client<4.0.0
2024-10-02 18:05:44,191 - INFO - file_cache is only supported with oauth2client<4.0.0
2024-10-02 18:05:44,196 - INFO - file_cache is only supported with oauth2client<4.0.0
2024-10-02 18:05:44,323 - WARNING - No hostname was supplied. Reverting to default 'localhost'
2024-10-02 18:05:50,509 - ERROR - Internal Server Error: /actualizar/
Traceback (most recent call last):
  File "/usr/local/lib/python3.10/site-packages/kombu/utils/functional.py", line 32, in __call__
    return self.__value__
AttributeError: 'ChannelPromise' object has no attribute '__value__'

During handling of the above exception, another exception occurred:

Traceback (most recent call last):
  File "/usr/local/lib/python3.10/site-packages/kombu/connection.py", line 472, in _reraise_as_library_errors
    yield
  File "/usr/local/lib/python3.10/site-packages/kombu/connection.py", line 459, in _ensure_connection
    return retry_over_time(
  File "/usr/local/lib/python3.10/site-packages/kombu/utils/functional.py", line 318, in retry_over_time
    return fun(*args, **kwargs)
  File "/usr/local/lib/python3.10/site-packages/kombu/connection.py", line 934, in _connection_factory
    self._connection = self._establish_connection()
  File "/usr/local/lib/python3.10/site-packages/kombu/connection.py", line 860, in _establish_connection
    conn = self.transport.establish_connection()
  File "/usr/local/lib/python3.10/site-packages/kombu/transport/pyamqp.py", line 203, in establish_connection
    conn.connect()
  File "/usr/local/lib/python3.10/site-packages/amqp/connection.py", line 324, in connect
    self.transport.connect()
  File "/usr/local/lib/python3.10/site-packages/amqp/transport.py", line 129, in connect
    self._connect(self.host, self.port, self.connect_timeout)
  File "/usr/local/lib/python3.10/site-packages/amqp/transport.py", line 184, in _connect
    self.sock.connect(sa)
ConnectionRefusedError: [Errno 111] Connection refused

The above exception was the direct cause of the following exception:

Traceback (most recent call last):
  File "/usr/local/lib/python3.10/site-packages/django/core/handlers/exception.py", line 55, in inner
    response = get_response(request)
  File "/usr/local/lib/python3.10/site-packages/django/core/handlers/base.py", line 197, in _get_response
    response = wrapped_callback(request, *callback_args, **callback_kwargs)
  File "/usr/local/lib/python3.10/site-packages/django/views/generic/base.py", line 84, in view
    return self.dispatch(request, *args, **kwargs)
  File "/usr/local/lib/python3.10/site-packages/django/views/generic/base.py", line 119, in dispatch
    return handler(request, *args, **kwargs)
  File "/app/actualizador/views.py", line 121, in post
    task = recolectar_procesar.delay()  # Ejecuta la tarea de Celery
  File "/usr/local/lib/python3.10/site-packages/celery/app/task.py", line 444, in delay
    return self.apply_async(args, kwargs)
  File "/usr/local/lib/python3.10/site-packages/celery/app/task.py", line 594, in apply_async
    return app.send_task(
  File "/usr/local/lib/python3.10/site-packages/celery/app/base.py", line 801, in send_task
    amqp.send_task_message(P, name, message, **options)
  File "/usr/local/lib/python3.10/site-packages/celery/app/amqp.py", line 518, in send_task_message
    ret = producer.publish(
  File "/usr/local/lib/python3.10/site-packages/kombu/messaging.py", line 186, in publish
    return _publish(
  File "/usr/local/lib/python3.10/site-packages/kombu/connection.py", line 556, in _ensured
    return fun(*args, **kwargs)
  File "/usr/local/lib/python3.10/site-packages/kombu/messaging.py", line 195, in _publish
    channel = self.channel
  File "/usr/local/lib/python3.10/site-packages/kombu/messaging.py", line 218, in _get_channel
    channel = self._channel = channel()
  File "/usr/local/lib/python3.10/site-packages/kombu/utils/functional.py", line 34, in __call__
    value = self.__value__ = self.__contract__()
  File "/usr/local/lib/python3.10/site-packages/kombu/messaging.py", line 234, in <lambda>
    channel = ChannelPromise(lambda: connection.default_channel)
  File "/usr/local/lib/python3.10/site-packages/kombu/connection.py", line 953, in default_channel
    self._ensure_connection(**conn_opts)
  File "/usr/local/lib/python3.10/site-packages/kombu/connection.py", line 458, in _ensure_connection
    with ctx():
  File "/usr/local/lib/python3.10/contextlib.py", line 153, in __exit__
    self.gen.throw(typ, value, traceback)
  File "/usr/local/lib/python3.10/site-packages/kombu/connection.py", line 476, in _reraise_as_library_errors
    raise ConnectionError(str(exc)) from exc
kombu.exceptions.OperationalError: [Errno 111] Connection refused
2024-10-02 18:15:11,637 - INFO - /app/core_config/settings.py changed, reloading.
2024-10-02 18:15:21,613 - INFO - file_cache is only supported with oauth2client<4.0.0
2024-10-02 18:15:21,621 - INFO - file_cache is only supported with oauth2client<4.0.0
2024-10-02 18:15:21,627 - INFO - file_cache is only supported with oauth2client<4.0.0
2024-10-02 18:15:24,285 - INFO - file_cache is only supported with oauth2client<4.0.0
2024-10-02 18:15:24,291 - INFO - file_cache is only supported with oauth2client<4.0.0
2024-10-02 18:15:24,297 - INFO - file_cache is only supported with oauth2client<4.0.0
2024-10-02 18:15:24,443 - WARNING - No hostname was supplied. Reverting to default 'localhost'
2024-10-02 18:15:30,631 - ERROR - Internal Server Error: /actualizar/
Traceback (most recent call last):
  File "/usr/local/lib/python3.10/site-packages/kombu/utils/functional.py", line 32, in __call__
    return self.__value__
AttributeError: 'ChannelPromise' object has no attribute '__value__'

During handling of the above exception, another exception occurred:

Traceback (most recent call last):
  File "/usr/local/lib/python3.10/site-packages/kombu/connection.py", line 472, in _reraise_as_library_errors
    yield
  File "/usr/local/lib/python3.10/site-packages/kombu/connection.py", line 459, in _ensure_connection
    return retry_over_time(
  File "/usr/local/lib/python3.10/site-packages/kombu/utils/functional.py", line 318, in retry_over_time
    return fun(*args, **kwargs)
  File "/usr/local/lib/python3.10/site-packages/kombu/connection.py", line 934, in _connection_factory
    self._connection = self._establish_connection()
  File "/usr/local/lib/python3.10/site-packages/kombu/connection.py", line 860, in _establish_connection
    conn = self.transport.establish_connection()
  File "/usr/local/lib/python3.10/site-packages/kombu/transport/pyamqp.py", line 203, in establish_connection
    conn.connect()
  File "/usr/local/lib/python3.10/site-packages/amqp/connection.py", line 324, in connect
    self.transport.connect()
  File "/usr/local/lib/python3.10/site-packages/amqp/transport.py", line 129, in connect
    self._connect(self.host, self.port, self.connect_timeout)
  File "/usr/local/lib/python3.10/site-packages/amqp/transport.py", line 184, in _connect
    self.sock.connect(sa)
ConnectionRefusedError: [Errno 111] Connection refused

The above exception was the direct cause of the following exception:

Traceback (most recent call last):
  File "/usr/local/lib/python3.10/site-packages/django/core/handlers/exception.py", line 55, in inner
    response = get_response(request)
  File "/usr/local/lib/python3.10/site-packages/django/core/handlers/base.py", line 197, in _get_response
    response = wrapped_callback(request, *callback_args, **callback_kwargs)
  File "/usr/local/lib/python3.10/site-packages/django/views/generic/base.py", line 84, in view
    return self.dispatch(request, *args, **kwargs)
  File "/usr/local/lib/python3.10/site-packages/django/views/generic/base.py", line 119, in dispatch
    return handler(request, *args, **kwargs)
  File "/app/actualizador/views.py", line 121, in post
    task = recolectar_procesar.delay()  # Ejecuta la tarea de Celery
  File "/usr/local/lib/python3.10/site-packages/celery/app/task.py", line 444, in delay
    return self.apply_async(args, kwargs)
  File "/usr/local/lib/python3.10/site-packages/celery/app/task.py", line 594, in apply_async
    return app.send_task(
  File "/usr/local/lib/python3.10/site-packages/celery/app/base.py", line 801, in send_task
    amqp.send_task_message(P, name, message, **options)
  File "/usr/local/lib/python3.10/site-packages/celery/app/amqp.py", line 518, in send_task_message
    ret = producer.publish(
  File "/usr/local/lib/python3.10/site-packages/kombu/messaging.py", line 186, in publish
    return _publish(
  File "/usr/local/lib/python3.10/site-packages/kombu/connection.py", line 556, in _ensured
    return fun(*args, **kwargs)
  File "/usr/local/lib/python3.10/site-packages/kombu/messaging.py", line 195, in _publish
    channel = self.channel
  File "/usr/local/lib/python3.10/site-packages/kombu/messaging.py", line 218, in _get_channel
    channel = self._channel = channel()
  File "/usr/local/lib/python3.10/site-packages/kombu/utils/functional.py", line 34, in __call__
    value = self.__value__ = self.__contract__()
  File "/usr/local/lib/python3.10/site-packages/kombu/messaging.py", line 234, in <lambda>
    channel = ChannelPromise(lambda: connection.default_channel)
  File "/usr/local/lib/python3.10/site-packages/kombu/connection.py", line 953, in default_channel
    self._ensure_connection(**conn_opts)
  File "/usr/local/lib/python3.10/site-packages/kombu/connection.py", line 458, in _ensure_connection
    with ctx():
  File "/usr/local/lib/python3.10/contextlib.py", line 153, in __exit__
    self.gen.throw(typ, value, traceback)
  File "/usr/local/lib/python3.10/site-packages/kombu/connection.py", line 476, in _reraise_as_library_errors
    raise ConnectionError(str(exc)) from exc
kombu.exceptions.OperationalError: [Errno 111] Connection refused
2024-10-02 18:15:30,917 - WARNING - Not Found: /favicon.ico
2024-10-02 18:25:25,060 - INFO - /app/actualizador/views.py changed, reloading.
2024-10-02 18:28:25,032 - INFO - /app/actualizador/views.py changed, reloading.
2024-10-02 18:28:31,688 - INFO - file_cache is only supported with oauth2client<4.0.0
2024-10-02 18:28:31,695 - INFO - file_cache is only supported with oauth2client<4.0.0
2024-10-02 18:28:31,703 - INFO - file_cache is only supported with oauth2client<4.0.0
2024-10-02 18:28:35,075 - INFO - file_cache is only supported with oauth2client<4.0.0
2024-10-02 18:28:35,080 - INFO - file_cache is only supported with oauth2client<4.0.0
2024-10-02 18:28:35,084 - INFO - file_cache is only supported with oauth2client<4.0.0
2024-10-02 18:28:35,278 - ERROR - Internal Server Error: /actualizar/
Traceback (most recent call last):
  File "/usr/local/lib/python3.10/site-packages/django/core/handlers/exception.py", line 55, in inner
    response = get_response(request)
  File "/usr/local/lib/python3.10/site-packages/django/core/handlers/base.py", line 197, in _get_response
    response = wrapped_callback(request, *callback_args, **callback_kwargs)
  File "/usr/local/lib/python3.10/site-packages/django/views/generic/base.py", line 84, in view
    return self.dispatch(request, *args, **kwargs)
  File "/usr/local/lib/python3.10/site-packages/django/views/generic/base.py", line 119, in dispatch
    return handler(request, *args, **kwargs)
  File "/app/actualizador/views.py", line 122, in post
    task = app.send_task('actualizar.tasks.recolectar_procesar')
AttributeError: module 'celery.app' has no attribute 'send_task'
2024-10-02 18:29:43,567 - INFO - /app/actualizador/views.py changed, reloading.
2024-10-02 18:29:56,723 - INFO - file_cache is only supported with oauth2client<4.0.0
2024-10-02 18:29:56,731 - INFO - file_cache is only supported with oauth2client<4.0.0
2024-10-02 18:29:56,738 - INFO - file_cache is only supported with oauth2client<4.0.0
2024-10-02 18:32:10,816 - INFO - file_cache is only supported with oauth2client<4.0.0
2024-10-02 18:32:10,822 - INFO - file_cache is only supported with oauth2client<4.0.0
2024-10-02 18:32:10,827 - INFO - file_cache is only supported with oauth2client<4.0.0
2024-10-02 18:33:09,301 - INFO - /app/actualizador/views.py changed, reloading.
2024-10-02 18:33:24,402 - INFO - file_cache is only supported with oauth2client<4.0.0
2024-10-02 18:33:24,410 - INFO - file_cache is only supported with oauth2client<4.0.0
2024-10-02 18:33:24,418 - INFO - file_cache is only supported with oauth2client<4.0.0
2024-10-02 18:33:26,287 - INFO - file_cache is only supported with oauth2client<4.0.0
2024-10-02 18:33:26,294 - INFO - file_cache is only supported with oauth2client<4.0.0
2024-10-02 18:33:26,300 - INFO - file_cache is only supported with oauth2client<4.0.0
2024-10-02 18:33:28,900 - INFO - file_cache is only supported with oauth2client<4.0.0
2024-10-02 18:33:28,908 - INFO - file_cache is only supported with oauth2client<4.0.0
2024-10-02 18:33:28,915 - INFO - file_cache is only supported with oauth2client<4.0.0
2024-10-02 18:33:54,095 - INFO - /app/actualizador/views.py changed, reloading.
2024-10-02 18:34:03,680 - INFO - file_cache is only supported with oauth2client<4.0.0
2024-10-02 18:34:03,688 - INFO - file_cache is only supported with oauth2client<4.0.0
2024-10-02 18:34:03,695 - INFO - file_cache is only supported with oauth2client<4.0.0
2024-10-02 18:34:06,056 - INFO - file_cache is only supported with oauth2client<4.0.0
2024-10-02 18:34:06,062 - INFO - file_cache is only supported with oauth2client<4.0.0
2024-10-02 18:34:06,068 - INFO - file_cache is only supported with oauth2client<4.0.0
2024-10-03 09:55:50,661 - INFO - file_cache is only supported with oauth2client<4.0.0
2024-10-03 09:55:50,673 - INFO - file_cache is only supported with oauth2client<4.0.0
2024-10-03 09:55:50,715 - INFO - file_cache is only supported with oauth2client<4.0.0
2024-10-03 09:55:51,090 - INFO - Refreshing credentials due to a 401 response. Attempt 1/2.
2024-10-03 09:56:13,310 - INFO - file_cache is only supported with oauth2client<4.0.0
2024-10-03 09:56:13,315 - INFO - file_cache is only supported with oauth2client<4.0.0
2024-10-03 09:56:13,321 - INFO - file_cache is only supported with oauth2client<4.0.0
2024-10-03 09:56:13,593 - INFO - Refreshing credentials due to a 401 response. Attempt 1/2.
